Workbook

Sheet Análisis general
B1: Análisis del terremoto — resumen general | J1: Indicadores clave
B3: Departamento | C3: N.º de municipios | D3: Puntos totales | E3: Indice de Pobreza - 2025 | G3: Indicador | H3: Cifras | J3: Indicador | K3: Valor
B4: Antioquia | C4: 99 | D4: 241 | E4: 9.5 | G4: Magnitud y epicentro | H4: 7,4 - San José del Palmar(Chocó) | J4: Departamentos afectados | K4: 25
B5: Atlántico | C5: 1 | D5: 13 | E5: 8.2 | G5: Viviendas destruidas | H5: 26558 | J5: Municipios afectados | K5: 432
B6: Bogotá D.C. | C6: 1 | D6: 94 | E6: 2.2 | G6: Viviendas averiadas | H6: 127266 | J6: Puntos totales | K6: 3366
B7: Bolívar | C7: 3 | D7: 14 | E7: 17 | G7: edificios colapsados | H7: 197 | J7: Viviendas afectadas | K7: 153824
B8: Boyacá | C8: 2 | D8: 2 | E8: 6.4 | G8: Centros de salud | H8: 300
B9: Caldas | C9: 27 | D9: 654 | E9: 7.9 | G9: vías afectadas | H9: 403
B10: Caquetá | C10: 1 | D10: 1 | E10: 15 | G10: Centros educativos | H10: 3074
B11: Cauca | C11: 39 | D11: 93 | E11: 13
B12: Cesar | C12: 4 | D12: 7 | E12: 14.8 | G12: Fallecidos | H12: 304
B13: Chocó | C13: 27 | D13: 227 | E13: 30.8 | G13: Heridos | H13: 4400
B14: Córdoba | C14: 1 | D14: 3 | E14: 19.8 | G14: Desaparecidos | H14: 426
B15: Cundinamarca | C15: 58 | D15: 96 | E15: 4.1 | G15: Rescatados | H15: 357
B16: Huila | C16: 23 | D16: 71 | E16: 9.7
B17: La Guajira | C17: 1 | D17: 2 | E17: 40.1
B18: Magdalena | C18: 1 | D18: 3 | E18: 17.6
B19: Meta | C19: 3 | D19: 6 | E19: 12.3
B20: Nariño | C20: 17 | D20: 47 | E20: 13.2
B21: Norte de Santander | C21: 7 | D21: 11 | E21: 13.3
B22: Putumayo | C22: 1 | D22: 1 | E22: 13.6
B23: Quindío | C23: 12 | D23: 294 | E23: 6.7
B24: Risaralda | C24: 14 | D24: 353 | E24: 4.9
B25: Santander | C25: 5 | D25: 32 | E25: 6.9
B26: Sucre | C26: 2 | D26: 5 | E26: 25.4
B27: Tolima | C27: 42 | D27: 129 | E27: 12.2
... B29: Total general | C29: 432 | D29: 3366 | E29: 6300

Sheet Municipios completos
A1: Código DIVIPOLA | B1: Departamento | C1: Clasificación | D1: Priorizacion | E1: Priorizacion 3 (IPM peso 0.5, escala 0-9) | F1: Priorizacion 4 (sin Cruce_Proyectos, escala 0-9) | G1: Municipio | H1: Colegios CPE | I1: CPE | J1: Olimpiadas Nacional | K1: Colegios Olimpiadas | L1: Minculturas | M1: Asociacion turistica | N1: Puntos | O1: Edificación colapsada | P1: Edificación con daño | Q1: Vivienda afectada | R1: Hospital o centro de salud | S1: Escuela o colegio | T1: Patrimonio o templo | U1: Servicio público | V1: Vía afectada | W1: Deslizamiento | X1: Albergue o punto de atención | Y1: Punto de ayuda o acopio | Z1: Novedad o noticia | AA1: Toque de queda o restricción | AB1: Otro | AC1: Puente | AD1: Incendio | AE1: Saqueo | AF1: Robo | AG1: PRUEBA | AH1: Afectados Familia | AI1: Afectados Personas | AJ1: Indice de Pobreza - 2018 | AK1: ayudas | AL1: tipo de ayuda | AM1: Descripción / Tipo de afectación | AO1: Municipio (normalizado) | AP1: Departamento (normalizado) | AQ1: ¿Nombre ambiguo? | AR1: Clave de cruce | AS1: Cruce_Proyectos | AT1: Total_Daños | AU1: Daño_Norm (0-3) | AV1: Ayuda_Norm_Inv (0-3) | AX1: Umbrales de Daño (cuartiles) | AZ1: Ayuda_Norm_Bin (0/3) | BA1: Priorizacion 2 | BB1: IPM_Departamento (2025) | BC1: IPM_Norm (0-3) | BD1: Priorizacion 3 (IPM peso 0.5, escala 0-9) | BE1: Priorizacion 4 (sin Cruce_Proyectos, escala 0-9) | BF1: Umbrales de IPM (cuartiles)
A2: 66075 | B2: Cauca | C2: Sin clasificación oficial | D2: =AS2+AU2+AV2 -> 6 | E2: =BD2 -> 6.4285714 | F2: =BE2 -> 9 | G2: Balboa | H2: =IFERROR(IF($AQ2,INDEX(cpe!$C$2:$C$307,MATCH($AR2,cpe!$F$2:$F$307,0)),INDEX(cpe!$C$2:$C$307,MATCH($AR2,cpe!$D$2:$D$307,0))),"#N/D") -> #N/D | I2: =IFERROR(IF($AQ2,INDEX(cpe!$B$2:$B$307,MATCH($AR2,cpe!$F$2:$F$307,0)),INDEX(cpe!$B$2:$B$307,MATCH($AR2,cpe!$D$2:$D$307,0))),"#N/D") -> #N/D | J2: =IF($AQ2,"#N/D",IFERROR(INDEX(Olimpiadas!$B$2:$B$61,MATCH($AO2,Olimpiadas!$C$2:$C$61,0)),"#N/D")) -> #N/D | K2: =IF($AQ2,"#N/D",IFERROR(INDEX(Olimpiadas!$A$2:$A$61,MATCH($AO2,Olimpiadas!$C$2:$C$61,0)),"#N/D")) -> #N/D | L2: =IF($AQ2,"#N/D",IFERROR(INDEX(Minculturas!$A$2:$A$48,MATCH($AO2,Minculturas!$C$2:$C$48,0)),"#N/D")) -> #N/D | M2: =IF($AQ2,"#N/D",IFERROR(INDEX(Minculturas!$B$2:$B$48,MATCH($AO2,Minculturas!$C$2:$C$48,0)),"#N/D")) -> #N/D | N2: 11 | O2: 0 | P2: 3 | Q2: 1 | R2: 1 | S2: 3 | T2: 1 | U2: 1 | V2: 1 | W2: 0 | X2: 0 | Y2: 0 | Z2: 0 | AA2: 0 | AB2: 0 | AC2: 0 | AD2: 0 | AE2: 0 | AF2: 0 | AG2: =SUM(O2:X2) -> 11 | AJ2: 31.6 | AM2: Declarado afectado; sin lugar con nombre propio publicado en este registro. | AO2: =TRIM(SUBSTITUTE(SUBSTITUTE(SUBSTITUTE(SUBSTITUTE(SUBSTITUTE(SUBSTITUTE(SUBSTITUTE(SUBSTITUTE(SUBSTITUTE(LOWER(G2),"á","a"),"é","e"),"í","i"),"ó","o"),"ú","u"),"ñ","n"),"-"," "),","," "),"."," ")) -> balboa | AP2: =TRIM(SUBSTITUTE(SUBSTITUTE(SUBSTITUTE(SUBSTITUTE(SUBSTITUTE(SUBSTITUTE(SUBSTITUTE(SUBSTITUTE(SUBSTITUTE(LOWER(B2),"á","a"),"é","e"),"í","i"),"ó","o"),"ú","u"),"ñ","n"),"-"," "),","," "),"."," ")) -> cauca | AQ2: =COUNTIF($AO$2:$AO$433,AO2)>COUNTIFS($AO$2:$AO$433,AO2,$AP$2:$AP$433,AP2) -> TRUE | AR2: =IF(AQ2,AO2&"|"&AP2,AO2) -> balboa|cauca | AS2: =(I2<>"#N/D")+(J2<>"#N/D")+(L2<>"#N/D") -> 0 | AT2: =SUM(O2:X2) -> 11 | AU2: =IF(AT2<=$AY$2,0,IF(AT2<=$AY$3,1,IF(AT2<=$AY$4,2,3))) -> 3 | AV2: =IF(Y2<=$AY$7,3,IF(Y2<=$AY$8,2,IF(Y2<=$AY$9,1,0))) -> 3 | AX2: Q2 (50%) | AY2: =_xlfn.QUARTILE.INC($Y$2:$Y$433,2) -> 0 | AZ2: =IF(Y2=0,3,0) -> 3 | BA2: =AS2+AU2+AZ2 -> 6 | BB2: =IFERROR(INDEX('Análisis general'!$E$4:$E$28,MATCH($B2,'Análisis general'!$B$4:$B$28,0)),"") -> 13 | BC2: =IF(BB2="","",IF(BB2<=$BG$2,0,IF(BB2<=$BG$3,1,IF(BB2<=$BG$4,2,3)))) -> 3 | BD2: =(AS2+AU2+AZ2+(BC2/2))*(9/10.5) -> 6.4285714 | BE2: =(AU2+AZ2+(BC2/2))*(9/7.5) -> 9
A3: 27250 | B3: Chocó | C3: Sin clasificación oficial | D3: =AS3+AU3+AV3 -> 6 | E3: =BD3 -> 6.4285714 | F3: =BE3 -> 9 | G3: El Litoral del San Juan | H3: =IFERROR(IF($AQ3,INDEX(cpe!$C$2:$C$307,MATCH($AR3,cpe!$F$2:$F$307,0)),INDEX(cpe!$C$2:$C$307,MATCH($AR3,cpe!$D$2:$D$307,0))),"#N/D") -> #N/D | I3: =IFERROR(IF($AQ3,INDEX(cpe!$B$2:$B$307,MATCH($AR3,cpe!$F$2:$F$307,0)),INDEX(cpe!$B$2:$B$307,MATCH($AR3,cpe!$D$2:$D$307,0))),"#N/D") -> #N/D | J3: =IF($AQ3,"#N/D",IFERROR(INDEX(Olimpiadas!$B$2:$B$61,MATCH($AO3,Olimpiadas!$C$2:$C$61,0)),"#N/D")) -> #N/D | K3: =IF($AQ3,"#N/D",IFERROR(INDEX(Olimpiadas!$A$2:$A$61,MATCH($AO3,Olimpiadas!$C$2:$C$61,0)),"#N/D")) -> #N/D | L3: =IF($AQ3,"#N/D",IFERROR(INDEX(Minculturas!$A$2:$A$48,MATCH($AO3,Minculturas!$C$2:$C$48,0)),"#N/D")) -> #N/D | M3: =IF($AQ3,"#N/D",IFERROR(INDEX(Minculturas!$B$2:$B$48,MATCH($AO3,Minculturas!$C$2:$C$48,0)),"#N/D")) -> #N/D | N3: 11 | O3: 0 | P3: 0 | Q3: 4 | R3: 2 | S3: 2 | T3: 0 | U3: 1 | V3: 0 | W3: 0 | X3: 0 | Y3: 0 | Z3: 2 | AA3: 0 | AB3: 0 | AC3: 0 | AD3: 0 | AE3: 0 | AF3: 0 | AG3: =SUM(O3:X3) -> 9 | AH3: 525 | AI3: 1837 | AJ3: 83.1 | AM3: Declarado afectado; sin lugar con nombre propio publicado en este registro. | AO3: =TRIM(SUBSTITUTE(SUBSTITUTE(SUBSTITUTE(SUBSTITUTE(SUBSTITUTE(SUBSTITUTE(SUBSTITUTE(SUBSTITUTE(SUBSTITUTE(LOWER(G3),"á","a"),"é","e"),"í","i"),"ó","o"),"ú","u"),"ñ","n"),"-"," "),","," "),"."," ")) -> el litoral del san juan | AP3: =TRIM(SUBSTITUTE(SUBSTITUTE(SUBSTITUTE(SUBSTITUTE(SUBSTITUTE(SUBSTITUTE(SUBSTITUTE(SUBSTITUTE(SUBSTITUTE(LOWER(B3),"á","a"),"é","e"),"í","i"),"ó","o"),"ú","u"),"ñ","n"),"-"," "),","," "),"."," ")) -> choco | AQ3: =COUNTIF($AO$2:$AO$433,AO3)>COUNTIFS($AO$2:$AO$433,AO3,$AP$2:$AP$433,AP3) -> FALSE | AR3: =IF(AQ3,AO3&"|"&AP3,AO3) -> el litoral del san juan | AS3: =(I3<>"#N/D")+(J3<>"#N/D")+(L3<>"#N/D") -> 0 | AT3: =SUM(O3:X3) -> 9 | AU3: =IF(AT3<=$AY$2,0,IF(AT3<=$AY$3,1,IF(AT3<=$AY$4,2,3))) -> 3 | AV3: =IF(Y3<=$AY$7,3,IF(Y3<=$AY$8,2,IF(Y3<=$AY$9,1,0))) -> 3 | AX3: Umbrales de Ayuda (cuartiles) | AZ3: =IF(Y3=0,3,0) -> 3 | BA3: =AS3+AU3+AZ3 -> 6 | BB3: =IFERROR(INDEX('Análisis general'!$E$4:$E$28,MATCH($B3,'Análisis general'!$B$4:$B$28,0)),"") -> 30.8 | BC3: =IF(BB3="","",IF(BB3<=$BG$2,0,IF(BB3<=$BG$3,1,IF(BB3<=$BG$4,2,3)))) -> 3 | BD3: =(AS3+AU3+AZ3+(BC3/2))*(9/10.5) -> 6.4285714 | BE3: =(AU3+AZ3+(BC3/2))*(9/7.5) -> 9
A4: 27745 | B4: Chocó | C4: Afectación alta | D4: =AS4+AU4+AV4 -> 6 | E4: =BD4 -> 6.4285714 | F4: =BE4 -> 9 | G4: Sipí | H4: #N/D | I4: #N/D | J4: #N/D | K4: =IF($AQ4,"#N/D",IFERROR(INDEX(Olimpiadas!$A$2:$A$61,MATCH($AO4,Olimpiadas!$C$2:$C$61,0)),"#N/D")) -> #N/D | L4: =IF($AQ4,"#N/D",IFERROR(INDEX(Minculturas!$A$2:$A$48,MATCH($AO4,Minculturas!$C$2:$C$48,0)),"#N/D")) -> #N/D | M4: =IF($AQ4,"#N/D",IFERROR(INDEX(Minculturas!$B$2:$B$48,MATCH($AO4,Minculturas!$C$2:$C$48,0)),"#N/D")) -> #N/D | N4: 9 | O4: 0 | P4: 3 | Q4: 2 | R4: 1 | S4: 0 | T4: 0 | U4: 2 | V4: 0 | W4: 0 | X4: 0 | Y4: 0 | Z4: 1 | AA4: 0 | AB4: 0 | AC4: 0 | AD4: 0 | AE4: 0 | AF4: 0 | AG4: =SUM(O4:X4) -> 8 | AH4: 330 | AI4: 810 | AJ4: 69.7 | AM4: Afectaciones y zona próxima al entorno del evento. | AO4: =TRIM(SUBSTITUTE(SUBSTITUTE(SUBSTITUTE(SUBSTITUTE(SUBSTITUTE(SUBSTITUTE(SUBSTITUTE(SUBSTITUTE(SUBSTITUTE(LOWER(G4),"á","a"),"é","e"),"í","i"),"ó","o"),"ú","u"),"ñ","n"),"-"," "),","," "),"."," ")) -> sipi | AP4: =TRIM(SUBSTITUTE(SUBSTITUTE(SUBSTITUTE(SUBSTITUTE(SUBSTITUTE(SUBSTITUTE(SUBSTITUTE(SUBSTITUTE(SUBSTITUTE(LOWER(B4),"á","a"),"é","e"),"í","i"),"ó","o"),"ú","u"),"ñ","n"),"-"," "),","," "),"."," ")) -> choco | AQ4: =COUNTIF($AO$2:$AO$433,AO4)>COUNTIFS($AO$2:$AO$433,AO4,$AP$2:$AP$433,AP4) -> FALSE | AR4: =IF(AQ4,AO4&"|"&AP4,AO4) -> sipi | AS4: =(I4<>"#N/D")+(J4<>"#N/D")+(L4<>"#N/D") -> 0 | AT4: =SUM(O4:X4) -> 8 | AU4: =IF(AT4<=$AY$2,0,IF(AT4<=$AY$3,1,IF(AT4<=$AY$4,2,3))) -> 3 | AV4: =IF(Y4<=$AY$7,3,IF(Y4<=$AY$8,2,IF(Y4<=$AY$9,1,0))) -> 3 | AX4: Q1 (25%) | AY4: =_xlfn.QUARTILE.INC($Y$2:$Y$433,1) -> 0 | AZ4: =IF(Y4=0,3,0) -> 3 | BA4: =AS4+AU4+AZ4 -> 6 | BB4: =IFERROR(INDEX('Análisis general'!$E$4:$E$28,MATCH($B4,'Análisis general'!$B$4:$B$28,0)),"") -> 30.8 | BC4: =IF(BB4="","",IF(BB4<=$BG$2,0,IF(BB4<=$BG$3,1,IF(BB4<=$BG$4,2,3)))) -> 3 | BD4: =(AS4+AU4+AZ4+(BC4/2))*(9/10.5) -> 6.4285714 | BE4: =(AU4+AZ4+(BC4/2))*(9/7.5) -> 9
A5: 19318 | B5: Cauca | C5: Sin clasificación oficial | D5: =AS5+AU5+AV5 -> 6 | E5: =BD5 -> 6.4285714 | F5: =BE5 -> 9 | G5: Guapi | H5: =IFERROR(IF($AQ5,INDEX(cpe!$C$2:$C$307,MATCH($AR5,cpe!$F$2:$F$307,0)),INDEX(cpe!$C$2:$C$307,MATCH($AR5,cpe!$D$2:$D$307,0))),"#N/D") -> #N/D | I5: =IFERROR(IF($AQ5,INDEX(cpe!$B$2:$B$307,MATCH($AR5,cpe!$F$2:$F$307,0)),INDEX(cpe!$B$2:$B$307,MATCH($AR5,cpe!$D$2:$D$307,0))),"#N/D") -> #N/D | J5: =IF($AQ5,"#N/D",IFERROR(INDEX(Olimpiadas!$B$2:$B$61,MATCH($AO5,Olimpiadas!$C$2:$C$61,0)),"#N/D")) -> #N/D | K5: =IF($AQ5,"#N/D",IFERROR(INDEX(Olimpiadas!$A$2:$A$61,MATCH($AO5,Olimpiadas!$C$2:$C$61,0)),"#N/D")) -> #N/D | L5: =IF($AQ5,"#N/D",IFERROR(INDEX(Minculturas!$A$2:$A$48,MATCH($AO5,Minculturas!$C$2:$C$48,0)),"#N/D")) -> #N/D | M5: =IF($AQ5,"#N/D",IFERROR(INDEX(Minculturas!$B$2:$B$48,MATCH($AO5,Minculturas!$C$2:$C$48,0)),"#N/D")) -> #N/D | N5: 6 | O5: 0 | P5: 0 | Q5: 1 | R5: 0 | S5: 5 | T5: 0 | U5: 0 | V5: 0 | W5: 0 | X5: 0 | Y5: 0 | Z5: 0 | AA5: 0 | AB5: 0 | AC5: 0 | AD5: 0 | AE5: 0 | AF5: 0 | AG5: =SUM(O5:X5) -> 6 | AJ5: 68.9 | AM5: Declarado afectado; sin lugar con nombre propio publicado en este registro. | AO5: =TRIM(SUBSTITUTE(SUBSTITUTE(SUBSTITUTE(SUBSTITUTE(SUBSTITUTE(SUBSTITUTE(SUBSTITUTE(SUBSTITUTE(SUBSTITUTE(LOWER(G5),"á","a"),"é","e"),"í","i"),"ó","o"),"ú","u"),"ñ","n"),"-"," "),","," "),"."," ")) -> guapi | AP5: =TRIM(SUBSTITUTE(SUBSTITUTE(SUBSTITUTE(SUBSTITUTE(SUBSTITUTE(SUBSTITUTE(SUBSTITUTE(SUBSTITUTE(SUBSTITUTE(LOWER(B5),"á","a"),"é","e"),"í","i"),"ó","o"),"ú","u"),"ñ","n"),"-"," "),","," "),"."," ")) -> cauca | AQ5: =COUNTIF($AO$2:$AO$433,AO5)>COUNTIFS($AO$2:$AO$433,AO5,$AP$2:$AP$433,AP5) -> FALSE | AR5: =IF(AQ5,AO5&"|"&AP5,AO5) -> guapi | AS5: =(I5<>"#N/D")+(J5<>"#N/D")+(L5<>"#N/D") -> 0 | AT5: =SUM(O5:X5) -> 6 | AU5: =IF(AT5<=$AY$2,0,IF(AT5<=$AY$3,1,IF(AT5<=$AY$4,2,3))) -> 3 | AV5: =IF(Y5<=$AY$7,3,IF(Y5<=$AY$8,2,IF(Y5<=$AY$9,1,0))) -> 3 | AX5: Q1 (25%) | AY5: =_xlfn.QUARTILE.INC($Y$2:$Y$433,1) -> 0 | AZ5: =IF(Y5=0,3,0) -> 3 | BA5: =AS5+AU5+AZ5 -> 6 | BB5: =IFERROR(INDEX('Análisis general'!$E$4:$E$28,MATCH($B5,'Análisis general'!$B$4:$B$28,0)),"") -> 13 | BC5: =IF(BB5="","",IF(BB5<=$BG$2,0,IF(BB5<=$BG$3,1,IF(BB5<=$BG$4,2,3)))) -> 3 | BD5: =(AS5+AU5+AZ5+(BC5/2))*(9/10.5) -> 6.4285714 | BE5: =(AU5+AZ5+(BC5/2))*(9/7.5) -> 9
A6: 27205 | B6: Chocó | C6: Sin clasificación oficial | D6: =AS6+AU6+AV6 -> 6 | E6: =BD6 -> 6.4285714 | F6: =BE6 -> 9 | G6: Condoto | H6: =IFERROR(IF($AQ6,INDEX(cpe!$C$2:$C$307,MATCH($AR6,cpe!$F$2:$F$307,0)),INDEX(cpe!$C$2:$C$307,MATCH($AR6,cpe!$D$2:$D$307,0))),"#N/D") -> #N/D | I6: =IFERROR(IF($AQ6,INDEX(cpe!$B$2:$B$307,MATCH($AR6,cpe!$F$2:$F$307,0)),INDEX(cpe!$B$2:$B$307,MATCH($AR6,cpe!$D$2:$D$307,0))),"#N/D") -> #N/D | J6: =IF($AQ6,"#N/D",IFERROR(INDEX(Olimpiadas!$B$2:$B$61,MATCH($AO6,Olimpiadas!$C$2:$C$61,0)),"#N/D")) -> #N/D | K6: =IF($AQ6,"#N/D",IFERROR(INDEX(Olimpiadas!$A$2:$A$61,MATCH($AO6,Olimpiadas!$C$2:$C$61,0)),"#N/D")) -> #N/D | L6: =IF($AQ6,"#N/D",IFERROR(INDEX(Minculturas!$A$2:$A$48,MATCH($AO6,Minculturas!$C$2:$C$48,0)),"#N/D")) -> #N/D | M6: =IF($AQ6,"#N/D",IFERROR(INDEX(Minculturas!$B$2:$B$48,MATCH($AO6,Minculturas!$C$2:$C$48,0)),"#N/D")) -> #N/D | N6: 5 | O6: 0 | P6: 2 | Q6: 0 | R6: 0 | S6: 0 | T6: 0 | U6: 1 | V6: 1 | W6: 0 | X6: 1 | Y6: 0 | Z6: 0 | AA6: 0 | AB6: 0 | AC6: 0 | AD6: 0 | AE6: 0 | AF6: 0 | AG6: =SUM(O6:X6) -> 5 | AH6: 998 | AI6: 2888 | AJ6: 53.2 | AM6: Declarado afectado; sin lugar con nombre propio publicado en este registro. | AO6: =TRIM(SUBSTITUTE(SUBSTITUTE(SUBSTITUTE(SUBSTITUTE(SUBSTITUTE(SUBSTITUTE(SUBSTITUTE(SUBSTITUTE(SUBSTITUTE(LOWER(G6),"á","a"),"é","e"),"í","i"),"ó","o"),"ú","u"),"ñ","n"),"-"," "),","," "),"."," ")) -> condoto | AP6: =TRIM(SUBSTITUTE(SUBSTITUTE(SUBSTITUTE(SUBSTITUTE(SUBSTITUTE(SUBSTITUTE(SUBSTITUTE(SUBSTITUTE(SUBSTITUTE(LOWER(B6),"á","a"),"é","e"),"í","i"),"ó","o"),"ú","u"),"ñ","n"),"-"," "),","," "),"."," ")) -> choco | AQ6: =COUNTIF($AO$2:$AO$433,AO6)>COUNTIFS($AO$2:$AO$433,AO6,$AP$2:$AP$433,AP6) -> FALSE | AR6: =IF(AQ6,AO6&"|"&AP6,AO6) -> condoto | AS6: =(I6<>"#N/D")+(J6<>"#N/D")+(L6<>"#N/D") -> 0 | AT6: =SUM(O6:X6) -> 5 | AU6: =IF(AT6<=$AY$2,0,IF(AT6<=$AY$3,1,IF(AT6<=$AY$4,2,3))) -> 3 | AV6: =IF(Y6<=$AY$7,3,IF(Y6<=$AY$8,2,IF(Y6<=$AY$9,1,0))) -> 3 | AX6: Q3 (75%) | AY6: =_xlfn.QUARTILE.INC($Y$2:$Y$433,3) -> 1 | AZ6: =IF(Y6=0,3,0) -> 3 | BA6: =AS6+AU6+AZ6 -> 6 | BB6: =IFERROR(INDEX('Análisis general'!$E$4:$E$28,MATCH($B6,'Análisis general'!$B$4:$B$28,0)),"") -> 30.8 | BC6: =IF(BB6="","",IF(BB6<=$BG$2,0,IF(BB6<=$BG$3,1,IF(BB6<=$BG$4,2,3)))) -> 3 | BD6: =(AS6+AU6+AZ6+(BC6/2))*(9/10.5) -> 6.4285714 | BE6: =(AU6+AZ6+(BC6/2))*(9/7.5) -> 9
A7: 27245 | B7: Chocó | C7: Sin clasificación oficial | D7: =AS7+AU7+AV7 -> 6 | E7: =BD7 -> 6.4285714 | F7: =BE7 -> 9 | G7: El Carmen de Atrato | H7: =IFERROR(IF($AQ7,INDEX(cpe!$C$2:$C$307,MATCH($AR7,cpe!$F$2:$F$307,0)),INDEX(cpe!$C$2:$C$307,MATCH($AR7,cpe!$D$2:$D$307,0))),"#N/D") -> #N/D | I7: =IFERROR(IF($AQ7,INDEX(cpe!$B$2:$B$307,MATCH($AR7,cpe!$F$2:$F$307,0)),INDEX(cpe!$B$2:$B$307,MATCH($AR7,cpe!$D$2:$D$307,0))),"#N/D") -> #N/D | J7: =IF($AQ7,"#N/D",IFERROR(INDEX(Olimpiadas!$B$2:$B$61,MATCH($AO7,Olimpiadas!$C$2:$C$61,0)),"#N/D")) -> #N/D | K7: =IF($AQ7,"#N/D",IFERROR(INDEX(Olimpiadas!$A$2:$A$61,MATCH($AO7,Olimpiadas!$C$2:$C$61,0)),"#N/D")) -> #N/D | L7: =IF($AQ7,"#N/D",IFERROR(INDEX(Minculturas!$A$2:$A$48,MATCH($AO7,Minculturas!$C$2:$C$48,0)),"#N/D")) -> #N/D | M7: =IF($AQ7,"#N/D",IFERROR(INDEX(Minculturas!$B$2:$B$48,MATCH($AO7,Minculturas!$C$2:$C$48,0)),"#N/D")) -> #N/D | N7: 5 | O7: 0 | P7: 0 | Q7: 0 | R7: 1 | S7: 0 | T7: 0 | U7: 2 | V7: 1 | W7: 0 | X7: 1 | Y7: 0 | Z7: 0 | AA7: 0 | AB7: 0 | AC7: 0 | AD7: 0 | AE7: 0 | AF7: 0 | AG7: =SUM(O7:X7) -> 5 | AH7: 202 | AI7: 246 | AJ7: 54 | AM7: Declarado afectado; sin lugar con nombre propio publicado en este registro. | AO7: =TRIM(SUBSTITUTE(SUBSTITUTE(SUBSTITUTE(SUBSTITUTE(SUBSTITUTE(SUBSTITUTE(SUBSTITUTE(SUBSTITUTE(SUBSTITUTE(LOWER(G7),"á","a"),"é","e"),"í","i"),"ó","o"),"ú","u"),"ñ","n"),"-"," "),","," "),"."," ")) -> el carmen de atrato | AP7: =TRIM(SUBSTITUTE(SUBSTITUTE(SUBSTITUTE(SUBSTITUTE(SUBSTITUTE(SUBSTITUTE(SUBSTITUTE(SUBSTITUTE(SUBSTITUTE(LOWER(B7),"á","a"),"é","e"),"í","i"),"ó","o"),"ú","u"),"ñ","n"),"-"," "),","," "),"."," ")) -> choco | AQ7: =COUNTIF($AO$2:$AO$433,AO7)>COUNTIFS($AO$2:$AO$433,AO7,$AP$2:$AP$433,AP7) -> FALSE | AR7: =IF(AQ7,AO7&"|"&AP7,AO7) -> el carmen de atrato | AS7: =(I7<>"#N/D")+(J7<>"#N/D")+(L7<>"#N/D") -> 0 | AT7: =SUM(O7:X7) -> 5 | AU7: =IF(AT7<=$AY$2,0,IF(AT7<=$AY$3,1,IF(AT7<=$AY$4,2,3))) -> 3 | AV7: =IF(Y7<=$AY$7,3,IF(Y7<=$AY$8,2,IF(Y7<=$AY$9,1,0))) -> 3 | AZ7: =IF(Y7=0,3,0) -> 3 | BA7: =AS7+AU7+AZ7 -> 6 | BB7: =IFERROR(INDEX('Análisis general'!$E$4:$E$28,MATCH($B7,'Análisis general'!$B$4:$B$28,0)),"") -> 30.8 | BC7: =IF(BB7="","",IF(BB7<=$BG$2,0,IF(BB7<=$BG$3,1,IF(BB7<=$BG$4,2,3)))) -> 3 | BD7: =(AS7+AU7+AZ7+(BC7/2))*(9/10.5) -> 6.4285714 | BE7: =(AU7+AZ7+(BC7/2))*(9/7.5) -> 9
A8: 41298 | B8: Huila | C8: Sin clasificación oficial | D8: =AS8+AU8+AV8 -> 8 | E8: =BD8 -> 8.1428571 | F8: =BE8 -> 9 | G8: Garzón | H8: =IFERROR(IF($AQ8,INDEX(cpe!$C$2:$C$307,MATCH($AR8,cpe!$F$2:$F$307,0)),INDEX(cpe!$C$2:$C$307,MATCH($AR8,cpe!$D$2:$D$307,0))),"#N/D") -> Centro Etnoeducativo No. 21 Aralia | I8: =IFERROR(IF($AQ8,INDEX(cpe!$B$2:$B$307,MATCH($AR8,cpe!$F$2:$F$307,0)),INDEX(cpe!$B$2:$B$307,MATCH($AR8,cpe!$D$2:$D$307,0))),"#N/D") -> Garzón | J8: =IF($AQ8,"#N/D",IFERROR(INDEX(Olimpiadas!$B$2:$B$61,MATCH($AO8,Olimpiadas!$C$2:$C$61,0)),"#N/D")) -> Garzón | K8: =IF($AQ8,"#N/D",IFERROR(INDEX(Olimpiadas!$A$2:$A$61,MATCH($AO8,Olimpiadas!$C$2:$C$61,0)),"#N/D")) -> INSTITUCIÓN EDUCATIVA TULIO ARBELÁEZ | L8: =IF($AQ8,"#N/D",IFERROR(INDEX(Minculturas!$A$2:$A$48,MATCH($AO8,Minculturas!$C$2:$C$48,0)),"#N/D")) -> #N/D | M8: =IF($AQ8,"#N/D",IFERROR(INDEX(Minculturas!$B$2:$B$48,MATCH($AO8,Minculturas!$C$2:$C$48,0)),"#N/D")) -> #N/D | N8: 5 | O8: 0 | P8: 1 | Q8: 0 | R8: 0 | S8: 4 | T8: 0 | U8: 0 | V8: 0 | W8: 0 | X8: 0 | Y8: 0 | Z8: 0 | AA8: 0 | AB8: 0 | AC8: 0 | AD8: 0 | AE8: 0 | AF8: 0 | AG8: =SUM(O8:X8) -> 5 | AJ8: 32 | AM8: Declarado afectado; sin lugar con nombre propio publicado en este registro. | AO8: =TRIM(SUBSTITUTE(SUBSTITUTE(SUBSTITUTE(SUBSTITUTE(SUBSTITUTE(SUBSTITUTE(SUBSTITUTE(SUBSTITUTE(SUBSTITUTE(LOWER(G8),"á","a"),"é","e"),"í","i"),"ó","o"),"ú","u"),"ñ","n"),"-"," "),","," "),"."," ")) -> garzon | AP8: =TRIM(SUBSTITUTE(SUBSTITUTE(SUBSTITUTE(SUBSTITUTE(SUBSTITUTE(SUBSTITUTE(SUBSTITUTE(SUBSTITUTE(SUBSTITUTE(LOWER(B8),"á","a"),"é","e"),"í","i"),"ó","o"),"ú","u"),"ñ","n"),"-"," "),","," "),"."," ")) -> huila | AQ8: =COUNTIF($AO$2:$AO$433,AO8)>COUNTIFS($AO$2:$AO$433,AO8,$AP$2:$AP$433,AP8) -> FALSE | AR8: =IF(AQ8,AO8&"|"&AP8,AO8) -> garzon | AS8: =(I8<>"#N/D")+(J8<>"#N/D")+(L8<>"#N/D") -> 2 | AT8: =SUM(O8:X8) -> 5 | AU8: =IF(AT8<=$AY$2,0,IF(AT8<=$AY$3,1,IF(AT8<=$AY$4,2,3))) -> 3 | AV8: =IF(Y8<=$AY$7,3,IF(Y8<=$AY$8,2,IF(Y8<=$AY$9,1,0))) -> 3 | AX8: Q2 (50%) | AY8: =_xlfn.QUARTILE.INC($AT$2:$AT$433,1) -> 0 | AZ8: =IF(Y8=0,3,0) -> 3 | BA8: =AS8+AU8+AZ8 -> 8 | BB8: =IFERROR(INDEX('Análisis general'!$E$4:$E$28,MATCH($B8,'Análisis general'!$B$4:$B$28,0)),"") -> 9.7 | BC8: =IF(BB8="","",IF(BB8<=$BG$2,0,IF(BB8<=$BG$3,1,IF(BB8<=$BG$4,2,3)))) -> 3 | BD8: =(AS8+AU8+AZ8+(BC8/2))*(9/10.5) -> 8.1428571 | BE8: =(AU8+AZ8+(BC8/2))*(9/7.5) -> 9 | BF8: Q1 (25%) | BG8: =_xlfn.QUARTILE.INC($BB$2:$BB$433,1) -> 4.9
A9: 41396 | B9: Huila | C9: Sin clasificación oficial | D9: =AS9+AU9+AV9 -> 8 | E9: =BD9 -> 8.1428571 | F9: =BE9 -> 9 | G9: La Plata | H9: =IFERROR(IF($AQ9,INDEX(cpe!$C$2:$C$307,MATCH($AR9,cpe!$F$2:$F$307,0)),INDEX(cpe!$C$2:$C$307,MATCH($AR9,cpe!$D$2:$D$307,0))),"#N/D") -> Institucion Educativa Zaragoza Tamarindo | I9: =IFERROR(IF($AQ9,INDEX(cpe!$B$2:$B$307,MATCH($AR9,cpe!$F$2:$F$307,0)),INDEX(cpe!$B$2:$B$307,MATCH($AR9,cpe!$D$2:$D$307,0))),"#N/D") -> La Plata | J9: =IF($AQ9,"#N/D",IFERROR(INDEX(Olimpiadas!$B$2:$B$61,MATCH($AO9,Olimpiadas!$C$2:$C$61,0)),"#N/D")) -> La Plata | K9: =IF($AQ9,"#N/D",IFERROR(INDEX(Olimpiadas!$A$2:$A$61,MATCH($AO9,Olimpiadas!$C$2:$C$61,0)),"#N/D")) -> INSTITUCIÓN EDUCATIVA EL CARMELO | L9: =IF($AQ9,"#N/D",IFERROR(INDEX(Minculturas!$A$2:$A$48,MATCH($AO9,Minculturas!$C$2:$C$48,0)),"#N/D")) -> #N/D | M9: =IF($AQ9,"#N/D",IFERROR(INDEX(Minculturas!$B$2:$B$48,MATCH($AO9,Minculturas!$C$2:$C$48,0)),"#N/D")) -> #N/D | N9: 5 | O9: 0 | P9: 0 | Q9: 3 | R9: 0 | S9: 2 | T9: 0 | U9: 0 | V9: 0 | W9: 0 | X9: 0 | Y9: 0 | Z9: 0 | AA9: 0 | AB9: 0 | AC9: 0 | AD9: 0 | AE9: 0 | AF9: 0 | AG9: =SUM(O9:X9) -> 5 | AH9: 16 | AI9: 39 | AJ9: 42.5 | AM9: Declarado afectado; sin lugar con nombre propio publicado en este registro. | AO9: =TRIM(SUBSTITUTE(SUBSTITUTE(SUBSTITUTE(SUBSTITUTE(SUBSTITUTE(SUBSTITUTE(SUBSTITUTE(SUBSTITUTE(SUBSTITUTE(LOWER(G9),"á","a"),"é","e"),"í","i"),"ó","o"),"ú","u"),"ñ","n"),"-"," "),","," "),"."," ")) -> la plata | AP9: =TRIM(SUBSTITUTE(SUBSTITUTE(SUBSTITUTE(SUBSTITUTE(SUBSTITUTE(SUBSTITUTE(SUBSTITUTE(SUBSTITUTE(SUBSTITUTE(LOWER(B9),"á","a"),"é","e"),"í","i"),"ó","o"),"ú","u"),"ñ","n"),"-"," "),","," "),"."," ")) -> huila | AQ9: =COUNTIF($AO$2:$AO$433,AO9)>COUNTIFS($AO$2:$AO$433,AO9,$AP$2:$AP$433,AP9) -> FALSE | AR9: =IF(AQ9,AO9&"|"&AP9,AO9) -> la plata | AS9: =(I9<>"#N/D")+(J9<>"#N/D")+(L9<>"#N/D") -> 2 | AT9: =SUM(O9:X9) -> 5 | AU9: =IF(AT9<=$AY$2,0,IF(AT9<=$AY$3,1,IF(AT9<=$AY$4,2,3))) -> 3 | AV9: =IF(Y9<=$AY$7,3,IF(Y9<=$AY$8,2,IF(Y9<=$AY$9,1,0))) -> 3 | AX9: Q3 (75%) | AY9: =_xlfn.QUARTILE.INC($AT$2:$AT$433,2) -> 1 | AZ9: =IF(Y9=0,3,0) -> 3 | BA9: =AS9+AU9+AZ9 -> 8 | BB9: =IFERROR(INDEX('Análisis general'!$E$4:$E$28,MATCH($B9,'Análisis general'!$B$4:$B$28,0)),"") -> 9.7 | BC9: =IF(BB9="","",IF(BB9<=$BG$2,0,IF(BB9<=$BG$3,1,IF(BB9<=$BG$4,2,3)))) -> 3 | BD9: =(AS9+AU9+AZ9+(BC9/2))*(9/10.5) -> 8.1428571 | BE9: =(AU9+AZ9+(BC9/2))*(9/7.5) -> 9 | BF9: Q2 (50%) | BG9: =_xlfn.QUARTILE.INC($BB$2:$BB$433,2) -> 9.5
A10: 73124 | B10: Tolima | C10: Sin clasificación oficial | D10: =AS10+AU10+AV10 -> 7 | E10: =BD10 -> 7.2857143 | F10: =BE10 -> 9 | G10: Cajamarca | H10: =IFERROR(IF($AQ10,INDEX(cpe!$C$2:$C$307,MATCH($AR10,cpe!$F$2:$F$307,0)),INDEX(cpe!$C$2:$C$307,MATCH($AR10,cpe!$D$2:$D$307,0))),"#N/D") -> Institucion Educativa Distrital Jose Eusebio Caro Colcaro | I10: =IFERROR(IF($AQ10,INDEX(cpe!$B$2:$B$307,MATCH($AR10,cpe!$F$2:$F$307,0)),INDEX(cpe!$B$2:$B$307,MATCH($AR10,cpe!$D$2:$D$307,0))),"#N/D") -> Cajamarca | J10: =IF($AQ10,"#N/D",IFERROR(INDEX(Olimpiadas!$B$2:$B$61,MATCH($AO10,Olimpiadas!$C$2:$C$61,0)),"#N/D")) -> #N/D | K10: =IF($AQ10,"#N/D",IFERROR(INDEX(Olimpiadas!$A$2:$A$61,MATCH($AO10,Olimpiadas!$C$2:$C$61,0)),"#N/D")) -> #N/D | L10: =IF($AQ10,"#N/D",IFERROR(INDEX(Minculturas!$A$2:$A$48,MATCH($AO10,Minculturas!$C$2:$C$48,0)),"#N/D")) -> #N/D | M10: =IF($AQ10,"#N/D",IFERROR(INDEX(Minculturas!$B$2:$B$48,MATCH($AO10,Minculturas!$C$2:$C$48,0)),"#N/D")) -> #N/D | N10: 7 | O10: 0 | P10: 0 | Q10: 1 | R10: 0 | S10: 0 | T10: 1 | U10: 1 | V10: 2 | W10: 2 | X10: 0 | Y10: 0 | Z10: 0 | AA10: 0 | AB10: 0 | AC10: 0 | AD10: 0 | AE10: 0 | AF10: 0 | AG10: =SUM(O10:X10) -> 7 | AJ10: 36.2 | AM10: Declarado afectado; sin lugar con nombre propio publicado en este registro. | AO10: =TRIM(SUBSTITUTE(SUBSTITUTE(SUBSTITUTE(SUBSTITUTE(SUBSTITUTE(SUBSTITUTE(SUBSTITUTE(SUBSTITUTE(SUBSTITUTE(LOWER(G10),"á","a"),"é","e"),"í","i"),"ó","o"),"ú","u"),"ñ","n"),"-"," "),","," "),"."," ")) -> cajamarca | AP10: =TRIM(SUBSTITUTE(SUBSTITUTE(SUBSTITUTE(SUBSTITUTE(SUBSTITUTE(SUBSTITUTE(SUBSTITUTE(SUBSTITUTE(SUBSTITUTE(LOWER(B10),"á","a"),"é","e"),"í","i"),"ó","o"),"ú","u"),"ñ","n"),"-"," "),","," "),"."," ")) -> tolima | AQ10: =COUNTIF($AO$2:$AO$433,AO10)>COUNTIFS($AO$2:$AO$433,AO10,$AP$2:$AP$433,AP10) -> FALSE | AR10: =IF(AQ10,AO10&"|"&AP10,AO10) -> cajamarca | AS10: =(I10<>"#N/D")+(J10<>"#N/D")+(L10<>"#N/D") -> 1 | AT10: =SUM(O10:X10) -> 7 | AU10: =IF(AT10<=$AY$2,0,IF(AT10<=$AY$3,1,IF(AT10<=$AY$4,2,3))) -> 3 | AV10: =IF(Y10<=$AY$7,3,IF(Y10<=$AY$8,2,IF(Y10<=$AY$9,1,0))) -> 3 | AZ10: =IF(Y10=0,3,0) -> 3 | BA10: =AS10+AU10+AZ10 -> 7 | BB10: =IFERROR(INDEX('Análisis general'!$E$4:$E$28,MATCH($B10,'Análisis general'!$B$4:$B$28,0)),"") -> 12.2 | BC10: =IF(BB10="","",IF(BB10<=$BG$2,0,IF(BB10<=$BG$3,1,IF(BB10<=$BG$4,2,3)))) -> 3 | BD10: =(AS10+AU10+AZ10+(BC10/2))*(9/10.5) -> 7.2857143 | BE10: =(AU10+AZ10+(BC10/2))*(9/7.5) -> 9
A11: 73678 | B11: Tolima | C11: Sin clasificación oficial | D11: =AS11+AU11+AV11 -> 7 | E11: =BD11 -> 7.2857143 | F11: =BE11 -> 9 | G11: San Luis | H11: Institucion Ednoeducativa Tecnica Nasawe´sx Fi´zni | I11: San Luis | J11: #N/D | K11: =IF($AQ11,"#N/D",IFERROR(INDEX(Olimpiadas!$A$2:$A$61,MATCH($AO11,Olimpiadas!$C$2:$C$61,0)),"#N/D")) -> #N/D | L11: =IF($AQ11,"#N/D",IFERROR(INDEX(Minculturas!$A$2:$A$48,MATCH($AO11,Minculturas!$C$2:$C$48,0)),"#N/D")) -> #N/D | M11: =IF($AQ11,"#N/D",IFERROR(INDEX(Minculturas!$B$2:$B$48,MATCH($AO11,Minculturas!$C$2:$C$48,0)),"#N/D")) -> #N/D | N11: 5 | O11: 0 | P11: 0 | Q11: 1 | R11: 1 | S11: 2 | T11: 0 | U11: 0 | V11: 1 | W11: 0 | X11: 0 | Y11: 0 | Z11: 0 | AA11: 0 | AB11: 0 | AC11: 0 | AD11: 0 | AE11: 0 | AF11: 0 | AG11: =SUM(O11:X11) -> 5 | AJ11: 39.4 | AM11: Declarado afectado; sin lugar con nombre propio publicado en este registro. | AO11: =TRIM(SUBSTITUTE(SUBSTITUTE(SUBSTITUTE(SUBSTITUTE(SUBSTITUTE(SUBSTITUTE(SUBSTITUTE(SUBSTITUTE(SUBSTITUTE(LOWER(G11),"á","a"),"é","e"),"í","i"),"ó","o"),"ú","u"),"ñ","n"),"-"," "),","," "),"."," ")) -> san luis | AP11: =TRIM(SUBSTITUTE(SUBSTITUTE(SUBSTITUTE(SUBSTITUTE(SUBSTITUTE(SUBSTITUTE(SUBSTITUTE(SUBSTITUTE(SUBSTITUTE(LOWER(B11),"á","a"),"é","e"),"í","i"),"ó","o"),"ú","u"),"ñ","n"),"-"," "),","," "),"."," ")) -> tolima | AQ11: =COUNTIF($AO$2:$AO$433,AO11)>COUNTIFS($AO$2:$AO$433,AO11,$AP$2:$AP$433,AP11) -> TRUE | AR11: =IF(AQ11,AO11&"|"&AP11,AO11) -> san luis|tolima | AS11: =(I11<>"#N/D")+(J11<>"#N/D")+(L11<>"#N/D") -> 1 | AT11: =SUM(O11:X11) -> 5 | AU11: =IF(AT11<=$AY$2,0,IF(AT11<=$AY$3,1,IF(AT11<=$AY$4,2,3))) -> 3 | AV11: =IF(Y11<=$AY$7,3,IF(Y11<=$AY$8,2,IF(Y11<=$AY$9,1,0))) -> 3 | AZ11: =IF(Y11=0,3,0) -> 3 | BA11: =AS11+AU11+AZ11 -> 7 | BB11: =IFERROR(INDEX('Análisis general'!$E$4:$E$28,MATCH($B11,'Análisis general'!$B$4:$B$28,0)),"") -> 12.2 | BC11: =IF(BB11="","",IF(BB11<=$BG$2,0,IF(BB11<=$BG$3,1,IF(BB11<=$BG$4,2,3)))) -> 3 | BD11: =(AS11+AU11+AZ11+(BC11/2))*(9/10.5) -> 7.2857143 | BE11: =(AU11+AZ11+(BC11/2))*(9/7.5) -> 9
A12: 41799 | B12: Huila | C12: Sin clasificación oficial | D12: =AS12+AU12+AV12 -> 6 | E12: =BD12 -> 6.4285714 | F12: =BE12 -> 9 | G12: Tello | H12: #N/D | I12: #N/D | J12: #N/D | K12: =IF($AQ12,"#N/D",IFERROR(INDEX(Olimpiadas!$A$2:$A$61,MATCH($AO12,Olimpiadas!$C$2:$C$61,0)),"#N/D")) -> #N/D | L12: =IF($AQ12,"#N/D",IFERROR(INDEX(Minculturas!$A$2:$A$48,MATCH($AO12,Minculturas!$C$2:$C$48,0)),"#N/D")) -> #N/D | M12: =IF($AQ12,"#N/D",IFERROR(INDEX(Minculturas!$B$2:$B$48,MATCH($AO12,Minculturas!$C$2:$C$48,0)),"#N/D")) -> #N/D | N12: 8 | O12: 0 | P12: 0 | Q12: 2 | R12: 1 | S12: 4 | T12: 0 | U12: 0 | V12: 1 | W12: 0 | X12: 0 | Y12: 0 | Z12: 0 | AA12: 0 | AB12: 0 | AC12: 0 | AD12: 0 | AE12: 0 | AF12: 0 | AG12: =SUM(O12:X12) -> 8 | AH12: 23 | AI12: 58 | AJ12: 44.5 | AM12: Declarado afectado; sin lugar con nombre propio publicado en este registro. | AO12: =TRIM(SUBSTITUTE(SUBSTITUTE(SUBSTITUTE(SUBSTITUTE(SUBSTITUTE(SUBSTITUTE(SUBSTITUTE(SUBSTITUTE(SUBSTITUTE(LOWER(G12),"á","a"),"é","e"),"í","i"),"ó","o"),"ú","u"),"ñ","n"),"-"," "),","," "),"."," ")) -> tello | AP12: =TRIM(SUBSTITUTE(SUBSTITUTE(SUBSTITUTE(SUBSTITUTE(SUBSTITUTE(SUBSTITUTE(SUBSTITUTE(SUBSTITUTE(SUBSTITUTE(LOWER(B12),"á","a"),"é","e"),"í","i"),"ó","o"),"ú","u"),"ñ","n"),"-"," "),","," "),"."," ")) -> huila | AQ12: =COUNTIF($AO$2:$AO$433,AO12)>COUNTIFS($AO$2:$AO$433,AO12,$AP$2:$AP$433,AP12) -> FALSE | AR12: =IF(AQ12,AO12&"|"&AP12,AO12) -> tello | AS12: =(I12<>"#N/D")+(J12<>"#N/D")+(L12<>"#N/D") -> 0 | AT12: =SUM(O12:X12) -> 8 | AU12: =IF(AT12<=$AY$2,0,IF(AT12<=$AY$3,1,IF(AT12<=$AY$4,2,3))) -> 3 | AV12: =IF(Y12<=$AY$7,3,IF(Y12<=$AY$8,2,IF(Y12<=$AY$9,1,0))) -> 3 | AZ12: =IF(Y12=0,3,0) -> 3 | BA12: =AS12+AU12+AZ12 -> 6 | BB12: =IFERROR(INDEX('Análisis general'!$E$4:$E$28,MATCH($B12,'Análisis general'!$B$4:$B$28,0)),"") -> 9.7 | BC12: =IF(BB12="","",IF(BB12<=$BG$2,0,IF(BB12<=$BG$3,1,IF(BB12<=$BG$4,2,3)))) -> 3 | BD12: =(AS12+AU12+AZ12+(BC12/2))*(9/10.5) -> 6.4285714 | BE12: =(AU12+AZ12+(BC12/2))*(9/7.5) -> 9
A13: 41078 | B13: Huila | C13: Sin clasificación oficial | D13: =AS13+AU13+AV13 -> 6 | E13: =BD13 -> 6.4285714 | F13: =BE13 -> 9 | G13: Baraya | H13: =IFERROR(IF($AQ13,INDEX(cpe!$C$2:$C$307,MATCH($AR13,cpe!$F$2:$F$307,0)),INDEX(cpe!$C$2:$C$307,MATCH($AR13,cpe!$D$2:$D$307,0))),"#N/D") -> #N/D | I13: =IFERROR(IF($AQ13,INDEX(cpe!$B$2:$B$307,MATCH($AR13,cpe!$F$2:$F$307,0)),INDEX(cpe!$B$2:$B$307,MATCH($AR13,cpe!$D$2:$D$307,0))),"#N/D") -> #N/D | J13: =IF($AQ13,"#N/D",IFERROR(INDEX(Olimpiadas!$B$2:$B$61,MATCH($AO13,Olimpiadas!$C$2:$C$61,0)),"#N/D")) -> #N/D | K13: =IF($AQ13,"#N/D",IFERROR(INDEX(Olimpiadas!$A$2:$A$61,MATCH($AO13,Olimpiadas!$C$2:$C$61,0)),"#N/D")) -> #N/D | L13: =IF($AQ13,"#N/D",IFERROR(INDEX(Minculturas!$A$2:$A$48,MATCH($AO13,Minculturas!$C$2:$C$48,0)),"#N/D")) -> #N/D | M13: =IF($AQ13,"#N/D",IFERROR(INDEX(Minculturas!$B$2:$B$48,MATCH($AO13,Minculturas!$C$2:$C$48,0)),"#N/D")) -> #N/D | N13: 5 | O13: 0 | P13: 1 | Q13: 0 | R13: 1 | S13: 3 | T13: 0 | U13: 0 | V13: 0 | W13: 0 | X13: 0 | Y13: 0 | Z13: 0 | AA13: 0 | AB13: 0 | AC13: 0 | AD13: 0 | AE13: 0 | AF13: 0 | AG13: =SUM(O13:X13) -> 5 | AJ13: 49.4 | AM13: Declarado afectado; sin lugar con nombre propio publicado en este registro. | AO13: =TRIM(SUBSTITUTE(SUBSTITUTE(SUBSTITUTE(SUBSTITUTE(SUBSTITUTE(SUBSTITUTE(SUBSTITUTE(SUBSTITUTE(SUBSTITUTE(LOWER(G13),"á","a"),"é","e"),"í","i"),"ó","o"),"ú","u"),"ñ","n"),"-"," "),","," "),"."," ")) -> baraya | AP13: =TRIM(SUBSTITUTE(SUBSTITUTE(SUBSTITUTE(SUBSTITUTE(SUBSTITUTE(SUBSTITUTE(SUBSTITUTE(SUBSTITUTE(SUBSTITUTE(LOWER(B13),"á","a"),"é","e"),"í","i"),"ó","o"),"ú","u"),"ñ","n"),"-"," "),","," "),"."," ")) -> huila | AQ13: =COUNTIF($AO$2:$AO$433,AO13)>COUNTIFS($AO$2:$AO$433,AO13,$AP$2:$AP$433,AP13) -> FALSE | AR13: =IF(AQ13,AO13&"|"&AP13,AO13) -> baraya | AS13: =(I13<>"#N/D")+(J13<>"#N/D")+(L13<>"#N/D") -> 0 | AT13: =SUM(O13:X13) -> 5 | AU13: =IF(AT13<=$AY$2,0,IF(AT13<=$AY$3,1,IF(AT13<=$AY$4,2,3))) -> 3 | AV13: =IF(Y13<=$AY$7,3,IF(Y13<=$AY$8,2,IF(Y13<=$AY$9,1,0))) -> 3 | AZ13: =IF(Y13=0,3,0) -> 3 | BA13: =AS13+AU13+AZ13 -> 6 | BB13: =IFERROR(INDEX('Análisis general'!$E$4:$E$28,MATCH($B13,'Análisis general'!$B$4:$B$28,0)),"") -> 9.7 | BC13: =IF(BB13="","",IF(BB13<=$BG$2,0,IF(BB13<=$BG$3,1,IF(BB13<=$BG$4,2,3)))) -> 3 | BD13: =(AS13+AU13+AZ13+(BC13/2))*(9/10.5) -> 6.4285714 | BE13: =(AU13+AZ13+(BC13/2))*(9/7.5) -> 9
A14: 52835 | B14: Nariño | C14: Sin clasificación oficial | D14: =AS14+AU14+AV14 -> 8 | E14: =BD14 -> 8.1428571 | F14: =BE14 -> 9 | G14: Tumaco | H14: Institucion Educativa Ana Elisa Cuenca Lara | I14: Tumaco | J14: Tumaco | K14: =IF($AQ14,"#N/D",IFERROR(INDEX(Olimpiadas!$A$2:$A$61,MATCH($AO14,Olimpiadas!$C$2:$C$61,0)),"#N/D")) -> INSTITUCIÓN EDUCATIVA SANTA TERESITA | L14: =IF($AQ14,"#N/D",IFERROR(INDEX(Minculturas!$A$2:$A$48,MATCH($AO14,Minculturas!$C$2:$C$48,0)),"#N/D")) -> #N/D | M14: =IF($AQ14,"#N/D",IFERROR(INDEX(Minculturas!$B$2:$B$48,MATCH($AO14,Minculturas!$C$2:$C$48,0)),"#N/D")) -> #N/D | N14: 3 | O14: 0 | P14: 2 | Q14: 0 | R14: 0 | S14: 0 | T14: 0 | U14: 1 | V14: 0 | W14: 0 | X14: 0 | Y14: 0 | Z14: 0 | AA14: 0 | AB14: 0 | AC14: 0 | AD14: 0 | AE14: 0 | AF14: 0 | AG14: =SUM(O14:X14) -> 3 | AJ14: 53.7 | AM14: Declarado afectado; sin lugar con nombre propio publicado en este registro. | AO14: =TRIM(SUBSTITUTE(SUBSTITUTE(SUBSTITUTE(SUBSTITUTE(SUBSTITUTE(SUBSTITUTE(SUBSTITUTE(SUBSTITUTE(SUBSTITUTE(LOWER(G14),"á","a"),"é","e"),"í","i"),"ó","o"),"ú","u"),"ñ","n"),"-"," "),","," "),"."," ")) -> tumaco | AP14: =TRIM(SUBSTITUTE(SUBSTITUTE(SUBSTITUTE(SUBSTITUTE(SUBSTITUTE(SUBSTITUTE(SUBSTITUTE(SUBSTITUTE(SUBSTITUTE(LOWER(B14),"á","a"),"é","e"),"í","i"),"ó","o"),"ú","u"),"ñ","n"),"-"," "),","," "),"."," ")) -> narino | AQ14: =COUNTIF($AO$2:$AO$433,AO14)>COUNTIFS($AO$2:$AO$433,AO14,$AP$2:$AP$433,AP14) -> FALSE | AR14: =IF(AQ14,AO14&"|"&AP14,AO14) -> tumaco | AS14: =(I14<>"#N/D")+(J14<>"#N/D")+(L14<>"#N/D") -> 2 | AT14: =SUM(O14:X14) -> 3 | AU14: =IF(AT14<=$AY$2,0,IF(AT14<=$AY$3,1,IF(AT14<=$AY$4,2,3))) -> 3 | AV14: =IF(Y14<=$AY$7,3,IF(Y14<=$AY$8,2,IF(Y14<=$AY$9,1,0))) -> 3 | AY14: =_xlfn.QUARTILE.INC($AT$2:$AT$433,3) -> 4 | AZ14: =IF(Y14=0,3,0) -> 3 | BA14: =AS14+AU14+AZ14 -> 8 | BB14: =IFERROR(INDEX('Análisis general'!$E$4:$E$28,MATCH($B14,'Análisis general'!$B$4:$B$28,0)),"") -> 13.2 | BC14: =IF(BB14="","",IF(BB14<=$BG$2,0,IF(BB14<=$BG$3,1,IF(BB14<=$BG$4,2,3)))) -> 3 | BD14: =(AS14+AU14+AZ14+(BC14/2))*(9/10.5) -> 8.1428571 | BE14: =(AU14+AZ14+(BC14/2))*(9/7.5) -> 9 | BF14: Q3 (75%) | BG14: =_xlfn.QUARTILE.INC($BB$2:$BB$433,3) -> 12.2
A15: 68081 | B15: Santander | C15: Sin clasificación oficial | D15: =AS15+AU15+AV15 -> 7 | E15: =BD15 -> 7.2857143 | F15: =BE15 -> 9 | G15: Barrancabermeja | H15: =IFERROR(IF($AQ15,INDEX(cpe!$C$2:$C$307,MATCH($AR15,cpe!$F$2:$F$307,0)),INDEX(cpe!$C$2:$C$307,MATCH($AR15,cpe!$D$2:$D$307,0))),"#N/D") -> Institucion Educativa Tecnica Maria Inmaculada de Pital de Megua | I15: =IFERROR(IF($AQ15,INDEX(cpe!$B$2:$B$307,MATCH($AR15,cpe!$F$2:$F$307,0)),INDEX(cpe!$B$2:$B$307,MATCH($AR15,cpe!$D$2:$D$307,0))),"#N/D") -> Barrancabermeja | J15: =IF($AQ15,"#N/D",IFERROR(INDEX(Olimpiadas!$B$2:$B$61,MATCH($AO15,Olimpiadas!$C$2:$C$61,0)),"#N/D")) -> #N/D | K15: =IF($AQ15,"#N/D",IFERROR(INDEX(Olimpiadas!$A$2:$A$61,MATCH($AO15,Olimpiadas!$C$2:$C$61,0)),"#N/D")) -> #N/D | L15: =IF($AQ15,"#N/D",IFERROR(INDEX(Minculturas!$A$2:$A$48,MATCH($AO15,Minculturas!$C$2:$C$48,0)),"#N/D")) -> #N/D | M15: =IF($AQ15,"#N/D",IFERROR(INDEX(Minculturas!$B$2:$B$48,MATCH($AO15,Minculturas!$C$2:$C$48,0)),"#N/D")) -> #N/D | N15: 16 | O15: 0 | P15: 2 | Q15: 5 | R15: 1 | S15: 8 | T15: 0 | U15: 0 | V15: 0 | W15: 0 | X15: 0 | Y15: 0 | Z15: 0 | AA15: 0 | AB15: 0 | AC15: 0 | AD15: 0 | AE15: 0 | AF15: 0 | AG15: =SUM(O15:X15) -> 16 | AJ15: 26.4 | AM15: Declarado afectado; sin lugar con nombre propio publicado en este registro. | AO15: =TRIM(SUBSTITUTE(SUBSTITUTE(SUBSTITUTE(SUBSTITUTE(SUBSTITUTE(SUBSTITUTE(SUBSTITUTE(SUBSTITUTE(SUBSTITUTE(LOWER(G15),"á","a"),"é","e"),"í","i"),"ó","o"),"ú","u"),"ñ","n"),"-"," "),","," "),"."," ")) -> barrancabermeja | AP15: =TRIM(SUBSTITUTE(SUBSTITUTE(SUBSTITUTE(SUBSTITUTE(SUBSTITUTE(SUBSTITUTE(SUBSTITUTE(SUBSTITUTE(SUBSTITUTE(LOWER(B15),"á","a"),"é","e"),"í","i"),"ó","o"),"ú","u"),"ñ","n"),"-"," "),","," "),"."," ")) -> santander | AQ15: =COUNTIF($AO$2:$AO$433,AO15)>COUNTIFS($AO$2:$AO$433,AO15,$AP$2:$AP$433,AP15) -> FALSE | AR15: =IF(AQ15,AO15&"|"&AP15,AO15) -> barrancabermeja | AS15: =(I15<>"#N/D")+(J15<>"#N/D")+(L15<>"#N/D") -> 1 | AT15: =SUM(O15:X15) -> 16 | AU15: =IF(AT15<=$AY$2,0,IF(AT15<=$AY$3,1,IF(AT15<=$AY$4,2,3))) -> 3 | AV15: =IF(Y15<=$AY$7,3,IF(Y15<=$AY$8,2,IF(Y15<=$AY$9,1,0))) -> 3 | AZ15: =IF(Y15=0,3,0) -> 3 | BA15: =AS15+AU15+AZ15 -> 7 | BB15: =IFERROR(INDEX('Análisis general'!$E$4:$E$28,MATCH($B15,'Análisis general'!$B$4:$B$28,0)),"") -> 6.9 | BC15: =IF(BB15="","",IF(BB15<=$BG$2,0,IF(BB15<=$BG$3,1,IF(BB15<=$BG$4,2,3)))) -> 3 | BD15: =(AS15+AU15+AZ15+(BC15/2))*(9/10.5) -> 7.2857143 | BE15: =(AU15+AZ15+(BC15/2))*(9/7.5) -> 9
A16: 63401 | B16: Quindío | C16: Sin clasificación oficial | D16: =AS16+AU16+AV16 -> 7 | E16: =BD16 -> 7.2857143 | F16: =BE16 -> 9 | G16: La Tebaida | H16: =IFERROR(IF($AQ16,INDEX(cpe!$C$2:$C$307,MATCH($AR16,cpe!$F$2:$F$307,0)),INDEX(cpe!$C$2:$C$307,MATCH($AR16,cpe!$D$2:$D$307,0))),"#N/D") -> Centro Educativo Puerto Lucas Margen Derecha | I16: =IFERROR(IF($AQ16,INDEX(cpe!$B$2:$B$307,MATCH($AR16,cpe!$F$2:$F$307,0)),INDEX(cpe!$B$2:$B$307,MATCH($AR16,cpe!$D$2:$D$307,0))),"#N/D") -> La Tebaida | J16: =IF($AQ16,"#N/D",IFERROR(INDEX(Olimpiadas!$B$2:$B$61,MATCH($AO16,Olimpiadas!$C$2:$C$61,0)),"#N/D")) -> #N/D | K16: =IF($AQ16,"#N/D",IFERROR(INDEX(Olimpiadas!$A$2:$A$61,MATCH($AO16,Olimpiadas!$C$2:$C$61,0)),"#N/D")) -> #N/D | L16: =IF($AQ16,"#N/D",IFERROR(INDEX(Minculturas!$A$2:$A$48,MATCH($AO16,Minculturas!$C$2:$C$48,0)),"#N/D")) -> #N/D | M16: =IF($AQ16,"#N/D",IFERROR(INDEX(Minculturas!$B$2:$B$48,MATCH($AO16,Minculturas!$C$2:$C$48,0)),"#N/D")) -> #N/D | N16: 13 | O16: 0 | P16: 3 | Q16: 2 | R16: 1 | S16: 0 | T16: 0 | U16: 4 | V16: 1 | W16: 0 | X16: 0 | Y16: 0 | Z16: 0 | AA16: 2 | AB16: 0 | AC16: 0 | AD16: 0 | AE16: 0 | AF16: 0 | AG16: =SUM(O16:X16) -> 11 | AH16: 64 | AI16: 204 | AJ16: 27.4 | AM16: Declarado afectado; sin lugar con nombre propio publicado en este registro. | AO16: =TRIM(SUBSTITUTE(SUBSTITUTE(SUBSTITUTE(SUBSTITUTE(SUBSTITUTE(SUBSTITUTE(SUBSTITUTE(SUBSTITUTE(SUBSTITUTE(LOWER(G16),"á","a"),"é","e"),"í","i"),"ó","o"),"ú","u"),"ñ","n"),"-"," "),","," "),"."," ")) -> la tebaida | AP16: =TRIM(SUBSTITUTE(SUBSTITUTE(SUBSTITUTE(SUBSTITUTE(SUBSTITUTE(SUBSTITUTE(SUBSTITUTE(SUBSTITUTE(SUBSTITUTE(LOWER(B16),"á","a"),"é","e"),"í","i"),"ó","o"),"ú","u"),"ñ","n"),"-"," "),","," "),"."," ")) -> quindio | AQ16: =COUNTIF($AO$2:$AO$433,AO16)>COUNTIFS($AO$2:$AO$433,AO16,$AP$2:$AP$433,AP16) -> FALSE | AR16: =IF(AQ16,AO16&"|"&AP16,AO16) -> la tebaida | AS16: =(I16<>"#N/D")+(J16<>"#N/D")+(L16<>"#N/D") -> 1 | AT16: =SUM(O16:X16) -> 11 | AU16: =IF(AT16<=$AY$2,0,IF(AT16<=$AY$3,1,IF(AT16<=$AY$4,2,3))) -> 3 | AV16: =IF(Y16<=$AY$7,3,IF(Y16<=$AY$8,2,IF(Y16<=$AY$9,1,0))) -> 3 | AZ16: =IF(Y16=0,3,0) -> 3 | BA16: =AS16+AU16+AZ16 -> 7 | BB16: =IFERROR(INDEX('Análisis general'!$E$4:$E$28,MATCH($B16,'Análisis general'!$B$4:$B$28,0)),"") -> 6.7 | BC16: =IF(BB16="","",IF(BB16<=$BG$2,0,IF(BB16<=$BG$3,1,IF(BB16<=$BG$4,2,3)))) -> 3 | BD16: =(AS16+AU16+AZ16+(BC16/2))*(9/10.5) -> 7.2857143 | BE16: =(AU16+AZ16+(BC16/2))*(9/7.5) -> 9
A17: 63272 | B17: Quindío | C17: Sin clasificación oficial | D17: =AS17+AU17+AV17 -> 7 | E17: =BD17 -> 7.2857143 | F17: =BE17 -> 9 | G17: Filandia | H17: =IFERROR(IF($AQ17,INDEX(cpe!$C$2:$C$307,MATCH($AR17,cpe!$F$2:$F$307,0)),INDEX(cpe!$C$2:$C$307,MATCH($AR17,cpe!$D$2:$D$307,0))),"#N/D") -> Inst Educ Tapias | I17: =IFERROR(IF($AQ17,INDEX(cpe!$B$2:$B$307,MATCH($AR17,cpe!$F$2:$F$307,0)),INDEX(cpe!$B$2:$B$307,MATCH($AR17,cpe!$D$2:$D$307,0))),"#N/D") -> Filandia | J17: =IF($AQ17,"#N/D",IFERROR(INDEX(Olimpiadas!$B$2:$B$61,MATCH($AO17,Olimpiadas!$C$2:$C$61,0)),"#N/D")) -> #N/D | K17: =IF($AQ17,"#N/D",IFERROR(INDEX(Olimpiadas!$A$2:$A$61,MATCH($AO17,Olimpiadas!$C$2:$C$61,0)),"#N/D")) -> #N/D | L17: =IF($AQ17,"#N/D",IFERROR(INDEX(Minculturas!$A$2:$A$48,MATCH($AO17,Minculturas!$C$2:$C$48,0)),"#N/D")) -> #N/D | M17: =IF($AQ17,"#N/D",IFERROR(INDEX(Minculturas!$B$2:$B$48,MATCH($AO17,Minculturas!$C$2:$C$48,0)),"#N/D")) -> #N/D | N17: 9 | O17: 0 | P17: 2 | Q17: 0 | R17: 0 | S17: 0 | T17: 2 | U17: 3 | V17: 2 | W17: 0 | X17: 0 | Y17: 0 | Z17: 0 | AA17: 0 | AB17: 0 | AC17: 0 | AD17: 0 | AE17: 0 | AF17: 0 | AG17: =SUM(O17:X17) -> 9 | AJ17: 18.1 | AM17: Declarado afectado; sin lugar con nombre propio publicado en este registro. | AO17: =TRIM(SUBSTITUTE(SUBSTITUTE(SUBSTITUTE(SUBSTITUTE(SUBSTITUTE(SUBSTITUTE(SUBSTITUTE(SUBSTITUTE(SUBSTITUTE(LOWER(G17),"á","a"),"é","e"),"í","i"),"ó","o"),"ú","u"),"ñ","n"),"-"," "),","," "),"."," ")) -> filandia | AP17: =TRIM(SUBSTITUTE(SUBSTITUTE(SUBSTITUTE(SUBSTITUTE(SUBSTITUTE(SUBSTITUTE(SUBSTITUTE(SUBSTITUTE(SUBSTITUTE(LOWER(B17),"á","a"),"é","e"),"í","i"),"ó","o"),"ú","u"),"ñ","n"),"-"," "),","," "),"."," ")) -> quindio | AQ17: =COUNTIF($AO$2:$AO$433,AO17)>COUNTIFS($AO$2:$AO$433,AO17,$AP$2:$AP$433,AP17) -> FALSE | AR17: =IF(AQ17,AO17&"|"&AP17,AO17) -> filandia | AS17: =(I17<>"#N/D")+(J17<>"#N/D")+(L17<>"#N/D") -> 1 | AT17: =SUM(O17:X17) -> 9 | AU17: =IF(AT17<=$AY$2,0,IF(AT17<=$AY$3,1,IF(AT17<=$AY$4,2,3))) -> 3 | AV17: =IF(Y17<=$AY$7,3,IF(Y17<=$AY$8,2,IF(Y17<=$AY$9,1,0))) -> 3 | AZ17: =IF(Y17=0,3,0) -> 3 | BA17: =AS17+AU17+AZ17 -> 7 | BB17: =IFERROR(INDEX('Análisis general'!$E$4:$E$28,MATCH($B17,'Análisis general'!$B$4:$B$28,0)),"") -> 6.7 | BC17: =IF(BB17="","",IF(BB17<=$BG$2,0,IF(BB17<=$BG$3,1,IF(BB17<=$BG$4,2,3)))) -> 3 | BD17: =(AS17+AU17+AZ17+(BC17/2))*(9/10.5) -> 7.2857143 | BE17: =(AU17+AZ17+(BC17/2))*(9/7.5) -> 9
A18: 27495 | B18: Chocó | C18: Sin clasificación oficial | D18: =AS18+AU18+AV18 -> 7 | E18: =BD18 -> 7.2857143 | F18: =BE18 -> 9 | G18: Nuquí | H18: =IFERROR(IF($AQ18,INDEX(cpe!$C$2:$C$307,MATCH($AR18,cpe!$F$2:$F$307,0)),INDEX(cpe!$C$2:$C$307,MATCH($AR18,cpe!$D$2:$D$307,0))),"#N/D") -> #N/D | I18: =IFERROR(IF($AQ18,INDEX(cpe!$B$2:$B$307,MATCH($AR18,cpe!$F$2:$F$307,0)),INDEX(cpe!$B$2:$B$307,MATCH($AR18,cpe!$D$2:$D$307,0))),"#N/D") -> #N/D | J18: =IF($AQ18,"#N/D",IFERROR(INDEX(Olimpiadas!$B$2:$B$61,MATCH($AO18,Olimpiadas!$C$2:$C$61,0)),"#N/D")) -> #N/D | K18: =IF($AQ18,"#N/D",IFERROR(INDEX(Olimpiadas!$A$2:$A$61,MATCH($AO18,Olimpiadas!$C$2:$C$61,0)),"#N/D")) -> #N/D | L18: =IF($AQ18,"#N/D",IFERROR(INDEX(Minculturas!$A$2:$A$48,MATCH($AO18,Minculturas!$C$2:$C$48,0)),"#N/D")) -> Nuquí | M18: =IF($AQ18,"#N/D",IFERROR(INDEX(Minculturas!$B$2:$B$48,MATCH($AO18,Minculturas!$C$2:$C$48,0)),"#N/D")) -> Fundación CLY Ambienta Serranías | N18: 3 | O18: 1 | P18: 0 | Q18: 0 | R18: 2 | S18: 0 | T18: 0 | U18: 0 | V18: 0 | W18: 0 | X18: 0 | Y18: 0 | Z18: 0 | AA18: 0 | AB18: 0 | AC18: 0 | AD18: 0 | AE18: 0 | AF18: 0 | AG18: =SUM(O18:X18) -> 3 | AH18: 54 | AI18: 71 | AJ18: 72.9 | AM18: Declarado afectado; sin lugar con nombre propio publicado en este registro. | AO18: =TRIM(SUBSTITUTE(SUBSTITUTE(SUBSTITUTE(SUBSTITUTE(SUBSTITUTE(SUBSTITUTE(SUBSTITUTE(SUBSTITUTE(SUBSTITUTE(LOWER(G18),"á","a"),"é","e"),"í","i"),"ó","o"),"ú","u"),"ñ","n"),"-"," "),","," "),"."," ")) -> nuqui | AP18: =TRIM(SUBSTITUTE(SUBSTITUTE(SUBSTITUTE(SUBSTITUTE(SUBSTITUTE(SUBSTITUTE(SUBSTITUTE(SUBSTITUTE(SUBSTITUTE(LOWER(B18),"á","a"),"é","e"),"í","i"),"ó","o"),"ú","u"),"ñ","n"),"-"," "),","," "),"."," ")) -> choco | AQ18: =COUNTIF($AO$2:$AO$433,AO18)>COUNTIFS($AO$2:$AO$433,AO18,$AP$2:$AP$433,AP18) -> FALSE | AR18: =IF(AQ18,AO18&"|"&AP18,AO18) -> nuqui | AS18: =(I18<>"#N/D")+(J18<>"#N/D")+(L18<>"#N/D") -> 1 | AT18: =SUM(O18:X18) -> 3 | AU18: =IF(AT18<=$AY$2,0,IF(AT18<=$AY$3,1,IF(AT18<=$AY$4,2,3))) -> 3 | AV18: =IF(Y18<=$AY$7,3,IF(Y18<=$AY$8,2,IF(Y18<=$AY$9,1,0))) -> 3 | AZ18: =IF(Y18=0,3,0) -> 3 | BA18: =AS18+AU18+AZ18 -> 7 | BB18: =IFERROR(INDEX('Análisis general'!$E$4:$E$28,MATCH($B18,'Análisis general'!$B$4:$B$28,0)),"") -> 30.8 | BC18: =IF(BB18="","",IF(BB18<=$BG$2,0,IF(BB18<=$BG$3,1,IF(BB18<=$BG$4,2,3)))) -> 3 | BD18: =(AS18+AU18+AZ18+(BC18/2))*(9/10.5) -> 7.2857143 | BE18: =(AU18+AZ18+(BC18/2))*(9/7.5) -> 9
A19: 27077 | B19: Chocó | C19: Sin clasificación oficial | D19: =AS19+AU19+AV19 -> 7 | E19: =BD19 -> 7.2857143 | F19: =BE19 -> 9 | G19: Bajo Baudó | H19: =IFERROR(IF($AQ19,INDEX(cpe!$C$2:$C$307,MATCH($AR19,cpe!$F$2:$F$307,0)),INDEX(cpe!$C$2:$C$307,MATCH($AR19,cpe!$D$2:$D$307,0))),"#N/D") -> IE de Samurindo | I19: =IFERROR(IF($AQ19,INDEX(cpe!$B$2:$B$307,MATCH($AR19,cpe!$F$2:$F$307,0)),INDEX(cpe!$B$2:$B$307,MATCH($AR19,cpe!$D$2:$D$307,0))),"#N/D") -> Bajo Baudó | J19: =IF($AQ19,"#N/D",IFERROR(INDEX(Olimpiadas!$B$2:$B$61,MATCH($AO19,Olimpiadas!$C$2:$C$61,0)),"#N/D")) -> #N/D | K19: =IF($AQ19,"#N/D",IFERROR(INDEX(Olimpiadas!$A$2:$A$61,MATCH($AO19,Olimpiadas!$C$2:$C$61,0)),"#N/D")) -> #N/D | L19: =IF($AQ19,"#N/D",IFERROR(INDEX(Minculturas!$A$2:$A$48,MATCH($AO19,Minculturas!$C$2:$C$48,0)),"#N/D")) -> #N/D | M19: =IF($AQ19,"#N/D",IFERROR(INDEX(Minculturas!$B$2:$B$48,MATCH($AO19,Minculturas!$C$2:$C$48,0)),"#N/D")) -> #N/D | N19: 6 | O19: 0 | P19: 0 | Q19: 2 | R19: 0 | S19: 0 | T19: 0 | U19: 1 | V19: 0 | W19: 0 | X19: 0 | Y19: 0 | Z19: 0 | AA19: 0 | AB19: 3 | AC19: 0 | AD19: 0 | AE19: 0 | AF19: 0 | AG19: =SUM(O19:X19) -> 3 | AH19: 285 | AI19: 630 | AJ19: 80.4 | AM19: Declarado afectado; sin lugar con nombre propio publicado en este registro. | AO19: =TRIM(SUBSTITUTE(SUBSTITUTE(SUBSTITUTE(SUBSTITUTE(SUBSTITUTE(SUBSTITUTE(SUBSTITUTE(SUBSTITUTE(SUBSTITUTE(LOWER(G19),"á","a"),"é","e"),"í","i"),"ó","o"),"ú","u"),"ñ","n"),"-"," "),","," "),"."," ")) -> bajo baudo | AP19: =TRIM(SUBSTITUTE(SUBSTITUTE(SUBSTITUTE(SUBSTITUTE(SUBSTITUTE(SUBSTITUTE(SUBSTITUTE(SUBSTITUTE(SUBSTITUTE(LOWER(B19),"á","a"),"é","e"),"í","i"),"ó","o"),"ú","u"),"ñ","n"),"-"," "),","," "),"."," ")) -> choco | AQ19: =COUNTIF($AO$2:$AO$433,AO19)>COUNTIFS($AO$2:$AO$433,AO19,$AP$2:$AP$433,AP19) -> FALSE | AR19: =IF(AQ19,AO19&"|"&AP19,AO19) -> bajo baudo | AS19: =(I19<>"#N/D")+(J19<>"#N/D")+(L19<>"#N/D") -> 1 | AT19: =SUM(O19:X19) -> 3 | AU19: =IF(AT19<=$AY$2,0,IF(AT19<=$AY$3,1,IF(AT19<=$AY$4,2,3))) -> 3 | AV19: =IF(Y19<=$AY$7,3,IF(Y19<=$AY$8,2,IF(Y19<=$AY$9,1,0))) -> 3 | AZ19: =IF(Y19=0,3,0) -> 3 | BA19: =AS19+AU19+AZ19 -> 7 | BB19: =IFERROR(INDEX('Análisis general'!$E$4:$E$28,MATCH($B19,'Análisis general'!$B$4:$B$28,0)),"") -> 30.8 | BC19: =IF(BB19="","",IF(BB19<=$BG$2,0,IF(BB19<=$BG$3,1,IF(BB19<=$BG$4,2,3)))) -> 3 | BD19: =(AS19+AU19+AZ19+(BC19/2))*(9/10.5) -> 7.2857143 | BE19: =(AU19+AZ19+(BC19/2))*(9/7.5) -> 9
A20: 52378 | B20: Nariño | C20: Sin clasificación oficial | D20: =AS20+AU20+AV20 -> 7 | E20: =BD20 -> 7.2857143 | F20: =BE20 -> 9 | G20: La Cruz | H20: =IFERROR(IF($AQ20,INDEX(cpe!$C$2:$C$307,MATCH($AR20,cpe!$F$2:$F$307,0)),INDEX(cpe!$C$2:$C$307,MATCH($AR20,cpe!$D$2:$D$307,0))),"#N/D") -> Institucion Educativa Rural San Sebastian | I20: =IFERROR(IF($AQ20,INDEX(cpe!$B$2:$B$307,MATCH($AR20,cpe!$F$2:$F$307,0)),INDEX(cpe!$B$2:$B$307,MATCH($AR20,cpe!$D$2:$D$307,0))),"#N/D") -> La Cruz | J20: =IF($AQ20,"#N/D",IFERROR(INDEX(Olimpiadas!$B$2:$B$61,MATCH($AO20,Olimpiadas!$C$2:$C$61,0)),"#N/D")) -> #N/D | K20: =IF($AQ20,"#N/D",IFERROR(INDEX(Olimpiadas!$A$2:$A$61,MATCH($AO20,Olimpiadas!$C$2:$C$61,0)),"#N/D")) -> #N/D | L20: =IF($AQ20,"#N/D",IFERROR(INDEX(Minculturas!$A$2:$A$48,MATCH($AO20,Minculturas!$C$2:$C$48,0)),"#N/D")) -> #N/D | M20: =IF($AQ20,"#N/D",IFERROR(INDEX(Minculturas!$B$2:$B$48,MATCH($AO20,Minculturas!$C$2:$C$48,0)),"#N/D")) -> #N/D | N20: 2 | O20: 0 | P20: 0 | Q20: 0 | R20: 2 | S20: 0 | T20: 0 | U20: 0 | V20: 0 | W20: 0 | X20: 0 | Y20: 0 | Z20: 0 | AA20: 0 | AB20: 0 | AC20: 0 | AD20: 0 | AE20: 0 | AF20: 0 | AG20: =SUM(O20:X20) -> 2 | AJ20: 27.8 | AM20: Declarado afectado; sin lugar con nombre propio publicado en este registro. | AO20: =TRIM(SUBSTITUTE(SUBSTITUTE(SUBSTITUTE(SUBSTITUTE(SUBSTITUTE(SUBSTITUTE(SUBSTITUTE(SUBSTITUTE(SUBSTITUTE(LOWER(G20),"á","a"),"é","e"),"í","i"),"ó","o"),"ú","u"),"ñ","n"),"-"," "),","," "),"."," ")) -> la cruz | AP20: =TRIM(SUBSTITUTE(SUBSTITUTE(SUBSTITUTE(SUBSTITUTE(SUBSTITUTE(SUBSTITUTE(SUBSTITUTE(SUBSTITUTE(SUBSTITUTE(LOWER(B20),"á","a"),"é","e"),"í","i"),"ó","o"),"ú","u"),"ñ","n"),"-"," "),","," "),"."," ")) -> narino | AQ20: =COUNTIF($AO$2:$AO$433,AO20)>COUNTIFS($AO$2:$AO$433,AO20,$AP$2:$AP$433,AP20) -> FALSE | AR20: =IF(AQ20,AO20&"|"&AP20,AO20) -> la cruz | AS20: =(I20<>"#N/D")+(J20<>"#N/D")+(L20<>"#N/D") -> 1 | AT20: =SUM(O20:X20) -> 2 | AU20: =IF(AT20<=$AY$2,0,IF(AT20<=$AY$3,1,IF(AT20<=$AY$4,2,3))) -> 3 | AV20: =IF(Y20<=$AY$7,3,IF(Y20<=$AY$8,2,IF(Y20<=$AY$9,1,0))) -> 3 | AZ20: =IF(Y20=0,3,0) -> 3 | BA20: =AS20+AU20+AZ20 -> 7 | BB20: =IFERROR(INDEX('Análisis general'!$E$4:$E$28,MATCH($B20,'Análisis general'!$B$4:$B$28,0)),"") -> 13.2 | BC20: =IF(BB20="","",IF(BB20<=$BG$2,0,IF(BB20<=$BG$3,1,IF(BB20<=$BG$4,2,3)))) -> 3 | BD20: =(AS20+AU20+AZ20+(BC20/2))*(9/10.5) -> 7.2857143 | BE20: =(AU20+AZ20+(BC20/2))*(9/7.5) -> 9
A21: 27430 | B21: Chocó | C21: Sin clasificación oficial | D21: =AS21+AU21+AV21 -> 7 | E21: =BD21 -> 7.2857143 | F21: =BE21 -> 9 | G21: Medio Baudó | H21: =IFERROR(IF($AQ21,INDEX(cpe!$C$2:$C$307,MATCH($AR21,cpe!$F$2:$F$307,0)),INDEX(cpe!$C$2:$C$307,MATCH($AR21,cpe!$D$2:$D$307,0))),"#N/D") -> Institucion Educativa Santa Teresa de Pachaquiaro | I21: =IFERROR(IF($AQ21,INDEX(cpe!$B$2:$B$307,MATCH($AR21,cpe!$F$2:$F$307,0)),INDEX(cpe!$B$2:$B$307,MATCH($AR21,cpe!$D$2:$D$307,0))),"#N/D") -> Medio Baudó | J21: =IF($AQ21,"#N/D",IFERROR(INDEX(Olimpiadas!$B$2:$B$61,MATCH($AO21,Olimpiadas!$C$2:$C$61,0)),"#N/D")) -> #N/D | K21: =IF($AQ21,"#N/D",IFERROR(INDEX(Olimpiadas!$A$2:$A$61,MATCH($AO21,Olimpiadas!$C$2:$C$61,0)),"#N/D")) -> #N/D | L21: =IF($AQ21,"#N/D",IFERROR(INDEX(Minculturas!$A$2:$A$48,MATCH($AO21,Minculturas!$C$2:$C$48,0)),"#N/D")) -> #N/D | M21: =IF($AQ21,"#N/D",IFERROR(INDEX(Minculturas!$B$2:$B$48,MATCH($AO21,Minculturas!$C$2:$C$48,0)),"#N/D")) -> #N/D | N21: 3 | O21: 0 | P21: 1 | Q21: 0 | R21: 0 | S21: 0 | T21: 0 | U21: 0 | V21: 0 | W21: 0 | X21: 1 | Y21: 0 | Z21: 0 | AA21: 0 | AB21: 1 | AC21: 0 | AD21: 0 | AE21: 0 | AF21: 0 | AG21: =SUM(O21:X21) -> 2 | AH21: 1008 | AI21: 2493 | AJ21: 80.2 | AM21: Declarado afectado; sin lugar con nombre propio publicado en este registro. | AO21: =TRIM(SUBSTITUTE(SUBSTITUTE(SUBSTITUTE(SUBSTITUTE(SUBSTITUTE(SUBSTITUTE(SUBSTITUTE(SUBSTITUTE(SUBSTITUTE(LOWER(G21),"á","a"),"é","e"),"í","i"),"ó","o"),"ú","u"),"ñ","n"),"-"," "),","," "),"."," ")) -> medio baudo | AP21: =TRIM(SUBSTITUTE(SUBSTITUTE(SUBSTITUTE(SUBSTITUTE(SUBSTITUTE(SUBSTITUTE(SUBSTITUTE(SUBSTITUTE(SUBSTITUTE(LOWER(B21),"á","a"),"é","e"),"í","i"),"ó","o"),"ú","u"),"ñ","n"),"-"," "),","," "),"."," ")) -> choco | AQ21: =COUNTIF($AO$2:$AO$433,AO21)>COUNTIFS($AO$2:$AO$433,AO21,$AP$2:$AP$433,AP21) -> FALSE | AR21: =IF(AQ21,AO21&"|"&AP21,AO21) -> medio baudo | AS21: =(I21<>"#N/D")+(J21<>"#N/D")+(L21<>"#N/D") -> 1 | AT21: =SUM(O21:X21) -> 2 | AU21: =IF(AT21<=$AY$2,0,IF(AT21<=$AY$3,1,IF(AT21<=$AY$4,2,3))) -> 3 | AV21: =IF(Y21<=$AY$7,3,IF(Y21<=$AY$8,2,IF(Y21<=$AY$9,1,0))) -> 3 | AZ21: =IF(Y21=0,3,0) -> 3 | BA21: =AS21+AU21+AZ21 -> 7 | BB21: =IFERROR(INDEX('Análisis general'!$E$4:$E$28,MATCH($B21,'Análisis general'!$B$4:$B$28,0)),"") -> 30.8 | BC21: =IF(BB21="","",IF(BB21<=$BG$2,0,IF(BB21<=$BG$3,1,IF(BB21<=$BG$4,2,3)))) -> 3 | BD21: =(AS21+AU21+AZ21+(BC21/2))*(9/10.5) -> 7.2857143 | BE21: =(AU21+AZ21+(BC21/2))*(9/7.5) -> 9
A22: 25612 | B22: Nariño | C22: Afectación media | D22: =AS22+AU22+AV22 -> 7 | E22: =BD22 -> 7.2857143 | F22: =BE22 -> 9 | G22: Ricaurte | H22: Institucion Educativa Luis Carlos Galan | I22: Ricaurte | J22: #N/D | K22: =IF($AQ22,"#N/D",IFERROR(INDEX(Olimpiadas!$A$2:$A$61,MATCH($AO22,Olimpiadas!$C$2:$C$61,0)),"#N/D")) -> #N/D | L22: =IF($AQ22,"#N/D",IFERROR(INDEX(Minculturas!$A$2:$A$48,MATCH($AO22,Minculturas!$C$2:$C$48,0)),"#N/D")) -> #N/D | M22: =IF($AQ22,"#N/D",IFERROR(INDEX(Minculturas!$B$2:$B$48,MATCH($AO22,Minculturas!$C$2:$C$48,0)),"#N/D")) -> #N/D | N22: 2 | O22: 0 | P22: 1 | Q22: 0 | R22: 1 | S22: 0 | T22: 0 | U22: 0 | V22: 0 | W22: 0 | X22: 0 | Y22: 0 | Z22: 0 | AA22: 0 | AB22: 0 | AC22: 0 | AD22: 0 | AE22: 0 | AF22: 0 | AG22: =SUM(O22:X22) -> 2 | AJ22: 17.5 | AM22: Declarado afectado; sin lugar con nombre propio publicado en este registro. | AO22: =TRIM(SUBSTITUTE(SUBSTITUTE(SUBSTITUTE(SUBSTITUTE(SUBSTITUTE(SUBSTITUTE(SUBSTITUTE(SUBSTITUTE(SUBSTITUTE(LOWER(G22),"á","a"),"é","e"),"í","i"),"ó","o"),"ú","u"),"ñ","n"),"-"," "),","," "),"."," ")) -> ricaurte | AP22: =TRIM(SUBSTITUTE(SUBSTITUTE(SUBSTITUTE(SUBSTITUTE(SUBSTITUTE(SUBSTITUTE(SUBSTITUTE(SUBSTITUTE(SUBSTITUTE(LOWER(B22),"á","a"),"é","e"),"í","i"),"ó","o"),"ú","u"),"ñ","n"),"-"," "),","," "),"."," ")) -> narino | AQ22: =COUNTIF($AO$2:$AO$433,AO22)>COUNTIFS($AO$2:$AO$433,AO22,$AP$2:$AP$433,AP22) -> TRUE | AR22: =IF(AQ22,AO22&"|"&AP22,AO22) -> ricaurte|narino | AS22: =(I22<>"#N/D")+(J22<>"#N/D")+(L22<>"#N/D") -> 1 | AT22: =SUM(O22:X22) -> 2 | AU22: =IF(AT22<=$AY$2,0,IF(AT22<=$AY$3,1,IF(AT22<=$AY$4,2,3))) -> 3 | AV22: =IF(Y22<=$AY$7,3,IF(Y22<=$AY$8,2,IF(Y22<=$AY$9,1,0))) -> 3 | AZ22: =IF(Y22=0,3,0) -> 3 | BA22: =AS22+AU22+AZ22 -> 7 | BB22: =IFERROR(INDEX('Análisis general'!$E$4:$E$28,MATCH($B22,'Análisis general'!$B$4:$B$28,0)),"") -> 13.2 | BC22: =IF(BB22="","",IF(BB22<=$BG$2,0,IF(BB22<=$BG$3,1,IF(BB22<=$BG$4,2,3)))) -> 3 | BD22: =(AS22+AU22+AZ22+(BC22/2))*(9/10.5) -> 7.2857143 | BE22: =(AU22+AZ22+(BC22/2))*(9/7.5) -> 9
A23: 17541 | B23: Caldas | C23: Sin clasificación oficial | D23: =AS23+AU23+AV23 -> 6 | E23: =BD23 -> 6.4285714 | F23: =BE23 -> 9 | G23: Pensilvania | H23: #N/D | I23: #N/D | J23: #N/D | K23: =IF($AQ23,"#N/D",IFERROR(INDEX(Olimpiadas!$A$2:$A$61,MATCH($AO23,Olimpiadas!$C$2:$C$61,0)),"#N/D")) -> #N/D | L23: =IF($AQ23,"#N/D",IFERROR(INDEX(Minculturas!$A$2:$A$48,MATCH($AO23,Minculturas!$C$2:$C$48,0)),"#N/D")) -> #N/D | M23: =IF($AQ23,"#N/D",IFERROR(INDEX(Minculturas!$B$2:$B$48,MATCH($AO23,Minculturas!$C$2:$C$48,0)),"#N/D")) -> #N/D | N23: 22 | O23: 0 | P23: 8 | Q23: 0 | R23: 3 | S23: 4 | T23: 2 | U23: 5 | V23: 0 | W23: 0 | X23: 0 | Y23: 0 | Z23: 0 | AA23: 0 | AB23: 0 | AC23: 0 | AD23: 0 | AE23: 0 | AF23: 0 | AG23: =SUM(O23:X23) -> 22 | AH23: 125 | AI23: 323 | AJ23: 37.3 | AM23: Daños y afectaciones en infraestructura. | AO23: =TRIM(SUBSTITUTE(SUBSTITUTE(SUBSTITUTE(SUBSTITUTE(SUBSTITUTE(SUBSTITUTE(SUBSTITUTE(SUBSTITUTE(SUBSTITUTE(LOWER(G23),"á","a"),"é","e"),"í","i"),"ó","o"),"ú","u"),"ñ","n"),"-"," "),","," "),"."," ")) -> pensilvania | AP23: =TRIM(SUBSTITUTE(SUBSTITUTE(SUBSTITUTE(SUBSTITUTE(SUBSTITUTE(SUBSTITUTE(SUBSTITUTE(SUBSTITUTE(SUBSTITUTE(LOWER(B23),"á","a"),"é","e"),"í","i"),"ó","o"),"ú","u"),"ñ","n"),"-"," "),","," "),"."," ")) -> caldas | AQ23: =COUNTIF($AO$2:$AO$433,AO23)>COUNTIFS($AO$2:$AO$433,AO23,$AP$2:$AP$433,AP23) -> FALSE | AR23: =IF(AQ23,AO23&"|"&AP23,AO23) -> pensilvania | AS23: =(I23<>"#N/D")+(J23<>"#N/D")+(L23<>"#N/D") -> 0 | AT23: =SUM(O23:X23) -> 22 | AU23: =IF(AT23<=$AY$2,0,IF(AT23<=$AY$3,1,IF(AT23<=$AY$4,2,3))) -> 3 | AV23: =IF(Y23<=$AY$7,3,IF(Y23<=$AY$8,2,IF(Y23<=$AY$9,1,0))) -> 3 | AZ23: =IF(Y23=0,3,0) -> 3 | BA23: =AS23+AU23+AZ23 -> 6 | BB23: =IFERROR(INDEX('Análisis general'!$E$4:$E$28,MATCH($B23,'Análisis general'!$B$4:$B$28,0)),"") -> 7.9 | BC23: =IF(BB23="","",IF(BB23<=$BG$2,0,IF(BB23<=$BG$3,1,IF(BB23<=$BG$4,2,3)))) -> 3 | BD23: =(AS23+AU23+AZ23+(BC23/2))*(9/10.5) -> 6.4285714 | BE23: =(AU23+AZ23+(BC23/2))*(9/7.5) -> 9
A24: 17653 | B24: Caldas | C24: Sin clasificación oficial | D24: =AS24+AU24+AV24 -> 6 | E24: =BD24 -> 6.4285714 | F24: =BE24 -> 9 | G24: Salamina | H24: #N/D | I24: #N/D | J24: #N/D | K24: =IF($AQ24,"#N/D",IFERROR(INDEX(Olimpiadas!$A$2:$A$61,MATCH($AO24,Olimpiadas!$C$2:$C$61,0)),"#N/D")) -> #N/D | L24: =IF($AQ24,"#N/D",IFERROR(INDEX(Minculturas!$A$2:$A$48,MATCH($AO24,Minculturas!$C$2:$C$48,0)),"#N/D")) -> #N/D | M24: =IF($AQ24,"#N/D",IFERROR(INDEX(Minculturas!$B$2:$B$48,MATCH($AO24,Minculturas!$C$2:$C$48,0)),"#N/D")) -> #N/D | N24: 21 | O24: 0 | P24: 1 | Q24: 7 | R24: 1 | S24: 6 | T24: 5 | U24: 0 | V24: 0 | W24: 0 | X24: 0 | Y24: 0 | Z24: 0 | AA24: 0 | AB24: 1 | AC24: 0 | AD24: 0 | AE24: 0 | AF24: 0 | AG24: =SUM(O24:X24) -> 20 | AH24: 30 | AI24: 81 | AJ24: 28.7 | AM24: Declarado afectado; sin lugar con nombre propio publicado en este registro. | AO24: =TRIM(SUBSTITUTE(SUBSTITUTE(SUBSTITUTE(SUBSTITUTE(SUBSTITUTE(SUBSTITUTE(SUBSTITUTE(SUBSTITUTE(SUBSTITUTE(LOWER(G24),"á","a"),"é","e"),"í","i"),"ó","o"),"ú","u"),"ñ","n"),"-"," "),","," "),"."," ")) -> salamina | AP24: =TRIM(SUBSTITUTE(SUBSTITUTE(SUBSTITUTE(SUBSTITUTE(SUBSTITUTE(SUBSTITUTE(SUBSTITUTE(SUBSTITUTE(SUBSTITUTE(LOWER(B24),"á","a"),"é","e"),"í","i"),"ó","o"),"ú","u"),"ñ","n"),"-"," "),","," "),"."," ")) -> caldas | AQ24: =COUNTIF($AO$2:$AO$433,AO24)>COUNTIFS($AO$2:$AO$433,AO24,$AP$2:$AP$433,AP24) -> FALSE | AR24: =IF(AQ24,AO24&"|"&AP24,AO24) -> salamina | AS24: =(I24<>"#N/D")+(J24<>"#N/D")+(L24<>"#N/D") -> 0 | AT24: =SUM(O24:X24) -> 20 | AU24: =IF(AT24<=$AY$2,0,IF(AT24<=$AY$3,1,IF(AT24<=$AY$4,2,3))) -> 3 | AV24: =IF(Y24<=$AY$7,3,IF(Y24<=$AY$8,2,IF(Y24<=$AY$9,1,0))) -> 3 | AZ24: =IF(Y24=0,3,0) -> 3 | BA24: =AS24+AU24+AZ24 -> 6 | BB24: =IFERROR(INDEX('Análisis general'!$E$4:$E$28,MATCH($B24,'Análisis general'!$B$4:$B$28,0)),"") -> 7.9 | BC24: =IF(BB24="","",IF(BB24<=$BG$2,0,IF(BB24<=$BG$3,1,IF(BB24<=$BG$4,2,3)))) -> 3 | BD24: =(AS24+AU24+AZ24+(BC24/2))*(9/10.5) -> 6.4285714 | BE24: =(AU24+AZ24+(BC24/2))*(9/7.5) -> 9
A25: 17042 | B25: Caldas | C25: Afectación alta | D25: =AS25+AU25+AV25 -> 6 | E25: =BD25 -> 6.4285714 | F25: =BE25 -> 9 | G25: Anserma | H25: =IFERROR(IF($AQ25,INDEX(cpe!$C$2:$C$307,MATCH($AR25,cpe!$F$2:$F$307,0)),INDEX(cpe!$C$2:$C$307,MATCH($AR25,cpe!$D$2:$D$307,0))),"#N/D") -> #N/D | I25: =IFERROR(IF($AQ25,INDEX(cpe!$B$2:$B$307,MATCH($AR25,cpe!$F$2:$F$307,0)),INDEX(cpe!$B$2:$B$307,MATCH($AR25,cpe!$D$2:$D$307,0))),"#N/D") -> #N/D | J25: =IF($AQ25,"#N/D",IFERROR(INDEX(Olimpiadas!$B$2:$B$61,MATCH($AO25,Olimpiadas!$C$2:$C$61,0)),"#N/D")) -> #N/D | K25: =IF($AQ25,"#N/D",IFERROR(INDEX(Olimpiadas!$A$2:$A$61,MATCH($AO25,Olimpiadas!$C$2:$C$61,0)),"#N/D")) -> #N/D | L25: =IF($AQ25,"#N/D",IFERROR(INDEX(Minculturas!$A$2:$A$48,MATCH($AO25,Minculturas!$C$2:$C$48,0)),"#N/D")) -> #N/D | M25: =IF($AQ25,"#N/D",IFERROR(INDEX(Minculturas!$B$2:$B$48,MATCH($AO25,Minculturas!$C$2:$C$48,0)),"#N/D")) -> #N/D | N25: 18 | O25: 0 | P25: 7 | Q25: 2 | R25: 1 | S25: 3 | T25: 1 | U25: 1 | V25: 0 | W25: 0 | X25: 0 | Y25: 0 | Z25: 0 | AA25: 0 | AB25: 3 | AC25: 0 | AD25: 0 | AE25: 0 | AF25: 0 | AG25: =SUM(O25:X25) -> 15 | AH25: 2 | AI25: 3 | AJ25: 32.5 | AM25: Afectaciones estructurales y daños en infraestructura. | AO25: =TRIM(SUBSTITUTE(SUBSTITUTE(SUBSTITUTE(SUBSTITUTE(SUBSTITUTE(SUBSTITUTE(SUBSTITUTE(SUBSTITUTE(SUBSTITUTE(LOWER(G25),"á","a"),"é","e"),"í","i"),"ó","o"),"ú","u"),"ñ","n"),"-"," "),","," "),"."," ")) -> anserma | AP25: =TRIM(SUBSTITUTE(SUBSTITUTE(SUBSTITUTE(SUBSTITUTE(SUBSTITUTE(SUBSTITUTE(SUBSTITUTE(SUBSTITUTE(SUBSTITUTE(LOWER(B25),"á","a"),"é","e"),"í","i"),"ó","o"),"ú","u"),"ñ","n"),"-"," "),","," "),"."," ")) -> caldas | AQ25: =COUNTIF($AO$2:$AO$433,AO25)>COUNTIFS($AO$2:$AO$433,AO25,$AP$2:$AP$433,AP25) -> FALSE | AR25: =IF(AQ25,AO25&"|"&AP25,AO25) -> anserma | AS25: =(I25<>"#N/D")+(J25<>"#N/D")+(L25<>"#N/D") -> 0 | AT25: =SUM(O25:X25) -> 15 | AU25: =IF(AT25<=$AY$2,0,IF(AT25<=$AY$3,1,IF(AT25<=$AY$4,2,3))) -> 3 | AV25: =IF(Y25<=$AY$7,3,IF(Y25<=$AY$8,2,IF(Y25<=$AY$9,1,0))) -> 3 | AZ25: =IF(Y25=0,3,0) -> 3 | BA25: =AS25+AU25+AZ25 -> 6 | BB25: =IFERROR(INDEX('Análisis general'!$E$4:$E$28,MATCH($B25,'Análisis general'!$B$4:$B$28,0)),"") -> 7.9 | BC25: =IF(BB25="","",IF(BB25<=$BG$2,0,IF(BB25<=$BG$3,1,IF(BB25<=$BG$4,2,3)))) -> 3 | BD25: =(AS25+AU25+AZ25+(BC25/2))*(9/10.5) -> 6.4285714 | BE25: =(AU25+AZ25+(BC25/2))*(9/7.5) -> 9
